Workbook

Sheet Leia-me
A1: Esmaltes Cone 6 — Planilha de formulação, custos e testes
A2: Linha inicial de 17 cores · oxidação · 1220–1240 °C · Fase 1 pincel → Fase 2 pó para mergulho
A5: Como usar
A6: 1. Matérias-Primas | B6: Substitua as análises químicas (%) e os preços pelos dados dos SEUS fornecedores. Os valores atuais são teóricos/típicos e os preços são estimativas ilustrativas.
A7: 2. Base A … Base E | B7: Cada aba é uma base. Edite materiais e quantidades (azul). A UMF é calculada sozinha e comparada com as faixas-alvo (verde = dentro, vermelho = ajustar).
A8: 3. Cores | B8: As 17 cores: base + colorantes (% sobre 100 da base). Custo de matéria-prima por kg calculado automaticamente.
A9: 4. Pincel | B9: FASE 1: receita do líquido para pincel — densidade-alvo e aditivos (CMC, bentonita, glicerina, defloculante, conservante) com custo.
A10: 5. Custos e Preço | B10: Fase 1 (potes para pincel) e Fase 2 (pó 500 g / 1 kg). Premissas em amarelo → preço mínimo e margem real com o preço praticado.
A11: 6. Testes | B11: Matriz de 136 placas (17 cores × 2 argilas × 2 e 3 demãos × 2 curvas). A 1ª linha é um exemplo.
A12: 7. Estabilidade | B12: Validade do líquido no pote: sedimento, mofo e densidade aos 7, 30 e 90 dias.
A13: 8. Curva de Queima | B13: Curva padrão e curva com resfriamento lento para indicar no rótulo.
A15: Legenda de cores
A16: Texto azul | B16: Dado de entrada que você pode editar
A17: Texto preto | B17: Fórmula — não editar
A18: Texto verde | B18: Vínculo com outra aba
A19: Fundo amarelo | B19: Premissa-chave para revisar
A21: Avisos importantes
A22: Receitas | B22: As receitas e % de colorantes são PONTOS DE PARTIDA para teste, não fórmulas prontas para venda. Valide tudo em placas de teste.
A23: Segurança alimentar | B23: Só rotule como "própria para alimentos" após ensaio de lixiviação (Pb/Cd e metais como Cu, Co) em laboratório acreditado (ref. ISO 6486).
A24: Saúde | B24: Sílica, cobalto, cobre e pigmentos: use exaustão e máscara PFF2/P3 ao pesar e misturar pós.
A25: Estratégia | B25: Fase 1 = líquido para pincel (produto pronto, maior valor por grama). Fase 2 = mesmo esmalte em pó para o ceramista preparar banho. As bases e cores são as mesmas nas duas fases.

Sheet Matérias-Primas
A1: Matérias-primas e colorantes
A2: Análise química em % (base queimada = sem PPC). Substitua pelos laudos dos fornecedores.
E3: Massa molar → | F3: 60.08 | G3: 101.96 | H3: 69.62 | I3: 61.98 | J3: 94.2 | K3: 29.88 | L3: 56.08 | M3: 40.3 | N3: 103.62 | O3: 81.38 | P3: 123.22 | Q3: 159.69 | R3: 79.87
A4: Material | B4: Tipo | C4: Fornecedor | D4: Preço (R$/kg) | E4: PPC (%) | F4: SiO2 (%) | G4: Al2O3 (%) | H4: B2O3 (%) | I4: Na2O (%) | J4: K2O (%) | K4: Li2O (%) | L4: CaO (%) | M4: MgO (%) | N4: SrO (%) | O4: ZnO (%) | P4: ZrO2 (%) | Q4: Fe2O3 (%) | R4: TiO2 (%) | S4: Fonte / observação
A5: Feldspato potássico | B5: Base | D5: 3.5 | E5: 0.3 | F5: 67 | G5: 18.5 | H5: 0 | I5: 3 | J5: 11 | K5: 0 | L5: 0.2 | M5: 0 | N5: 0 | O5: 0 | P5: 0 | Q5: 0.1 | R5: 0 | S5: Valor típico de feldspato potássico nacional
A6: Caulim | B6: Base | D6: 2.5 | E6: 13.9 | F6: 46.5 | G6: 39.5 | H6: 0 | I6: 0 | J6: 0 | K6: 0 | L6: 0 | M6: 0 | N6: 0 | O6: 0 | P6: 0 | Q6: 0.1 | R6: 0 | S6: Caulinita teórica
A7: Quartzo (sílica 325#) | B7: Base | D7: 2 | E7: 0 | F7: 100 | G7: 0 | H7: 0 | I7: 0 | J7: 0 | K7: 0 | L7: 0 | M7: 0 | N7: 0 | O7: 0 | P7: 0 | Q7: 0 | R7: 0 | S7: Teórico
A8: Wollastonita | B8: Base | D8: 8 | E8: 0 | F8: 51.7 | G8: 0 | H8: 0 | I8: 0 | J8: 0 | K8: 0 | L8: 48.3 | M8: 0 | N8: 0 | O8: 0 | P8: 0 | Q8: 0 | R8: 0 | S8: Teórico
A9: Carbonato de cálcio | B9: Base | D9: 2 | E9: 44 | F9: 0 | G9: 0 | H9: 0 | I9: 0 | J9: 0 | K9: 0 | L9: 56 | M9: 0 | N9: 0 | O9: 0 | P9: 0 | Q9: 0 | R9: 0 | S9: Teórico
A10: Dolomita | B10: Base | D10: 2 | E10: 47.7 | F10: 0 | G10: 0 | H10: 0 | I10: 0 | J10: 0 | K10: 0 | L10: 30.4 | M10: 21.9 | N10: 0 | O10: 0 | P10: 0 | Q10: 0 | R10: 0 | S10: Teórico
A11: Talco | B11: Base | D11: 4 | E11: 4.8 | F11: 63.5 | G11: 0 | H11: 0 | I11: 0 | J11: 0 | K11: 0 | L11: 0 | M11: 31.9 | N11: 0 | O11: 0 | P11: 0 | Q11: 0 | R11: 0 | S11: Teórico
A12: Carbonato de estrôncio | B12: Base | D12: 35 | E12: 29.8 | F12: 0 | G12: 0 | H12: 0 | I12: 0 | J12: 0 | K12: 0 | L12: 0 | M12: 0 | N12: 70.2 | O12: 0 | P12: 0 | Q12: 0 | R12: 0 | S12: Teórico
A13: Óxido de zinco | B13: Base | D13: 40 | E13: 0 | F13: 0 | G13: 0 | H13: 0 | I13: 0 | J13: 0 | K13: 0 | L13: 0 | M13: 0 | N13: 0 | O13: 100 | P13: 0 | Q13: 0 | R13: 0 | S13: Teórico
A14: Frita borácica | B14: Base | D14: 15 | E14: 0 | F14: 46.5 | G14: 0 | H14: 23.1 | I14: 10.3 | J14: 0 | K14: 0 | L14: 20.1 | M14: 0 | N14: 0 | O14: 0 | P14: 0 | Q14: 0 | R14: 0 | S14: Aproximação tipo Ferro 3134 — trocar pela ficha da frita nacional
A15: Carbonato de lítio | B15: Base | D15: 300 | E15: 59.6 | F15: 0 | G15: 0 | H15: 0 | I15: 0 | J15: 0 | K15: 40.4 | L15: 0 | M15: 0 | N15: 0 | O15: 0 | P15: 0 | Q15: 0 | R15: 0 | S15: Teórico
A16: Silicato de zircônio | B16: Colorante | D16: 25 | E16: 0 | F16: 32.8 | G16: 0 | H16: 0 | I16: 0 | J16: 0 | K16: 0 | L16: 0 | M16: 0 | N16: 0 | O16: 0 | P16: 67.2 | Q16: 0 | R16: 0 | S16: Opacificante — teórico
... A29: Conservante (isotiazolinona) | B29: Aditivo | D29: 80 | E29: 0 | F29: 0 | G29: 0 | H29: 0 | I29: 0 | J29: 0 | K29: 0 | L29: 0 | M29: 0 | N29: 0 | O29: 0 | P29: 0 | Q29: 0 | R29: 0 | S29: Aditivo pincel — biocida
A31: Linhas livres abaixo para novos materiais (mantenha o mesmo formato). Preços: estimativas ilustrativas de 2026 — substitua por cotações reais.

Sheet Base A
A1: Base A — Brilhante transparente
A2: Ponto de partida: base "20x5" adaptada a materiais nacionais.
E3: Contribuição em massa de cada óxido (g por 100 g de esmalte queimado não normalizado) →
A4: Material | B4: Quantidade (g) | C4: % normalizado | D4: Preço (R$/kg) | E4: SiO2 | F4: Al2O3 | G4: B2O3 | H4: Na2O | I4: K2O | J4: Li2O | K4: CaO | L4: MgO | M4: SrO | N4: ZnO | O4: ZrO2 | P4: Fe2O3 | Q4: TiO2
A5: Wollastonita | B5: 20 | C5: =IF(B5="","",B5/SUM($B$5:$B$14)) -> 0.2 | D5: =IF(A5="","",IFERROR(INDEX('Matérias-Primas'!$D$5:$D$45,MATCH(A5,'Matérias-Primas'!$A$5:$A$45,0)),0)) -> 8 | E5: =IF(A5="",0,C5*IFERROR(INDEX('Matérias-Primas'!$F$5:$F$45,MATCH(A5,'Matérias-Primas'!$A$5:$A$45,0)),0)) -> 10.34 | F5: =IF(A5="",0,C5*IFERROR(INDEX('Matérias-Primas'!$G$5:$G$45,MATCH(A5,'Matérias-Primas'!$A$5:$A$45,0)),0)) -> 0 | G5: =IF(A5="",0,C5*IFERROR(INDEX('Matérias-Primas'!$H$5:$H$45,MATCH(A5,'Matérias-Primas'!$A$5:$A$45,0)),0)) -> 0 | H5: =IF(A5="",0,C5*IFERROR(INDEX('Matérias-Primas'!$I$5:$I$45,MATCH(A5,'Matérias-Primas'!$A$5:$A$45,0)),0)) -> 0 | I5: =IF(A5="",0,C5*IFERROR(INDEX('Matérias-Primas'!$J$5:$J$45,MATCH(A5,'Matérias-Primas'!$A$5:$A$45,0)),0)) -> 0 | J5: =IF(A5="",0,C5*IFERROR(INDEX('Matérias-Primas'!$K$5:$K$45,MATCH(A5,'Matérias-Primas'!$A$5:$A$45,0)),0)) -> 0 | K5: =IF(A5="",0,C5*IFERROR(INDEX('Matérias-Primas'!$L$5:$L$45,MATCH(A5,'Matérias-Primas'!$A$5:$A$45,0)),0)) -> 9.66 | L5: =IF(A5="",0,C5*IFERROR(INDEX('Matérias-Primas'!$M$5:$M$45,MATCH(A5,'Matérias-Primas'!$A$5:$A$45,0)),0)) -> 0 | M5: =IF(A5="",0,C5*IFERROR(INDEX('Matérias-Primas'!$N$5:$N$45,MATCH(A5,'Matérias-Primas'!$A$5:$A$45,0)),0)) -> 0 | N5: =IF(A5="",0,C5*IFERROR(INDEX('Matérias-Primas'!$O$5:$O$45,MATCH(A5,'Matérias-Primas'!$A$5:$A$45,0)),0)) -> 0 | O5: =IF(A5="",0,C5*IFERROR(INDEX('Matérias-Primas'!$P$5:$P$45,MATCH(A5,'Matérias-Primas'!$A$5:$A$45,0)),0)) -> 0 | P5: =IF(A5="",0,C5*IFERROR(INDEX('Matérias-Primas'!$Q$5:$Q$45,MATCH(A5,'Matérias-Primas'!$A$5:$A$45,0)),0)) -> 0 | Q5: =IF(A5="",0,C5*IFERROR(INDEX('Matérias-Primas'!$R$5:$R$45,MATCH(A5,'Matérias-Primas'!$A$5:$A$45,0)),0)) -> 0
A6: Frita borácica | B6: 20 | C6: =IF(B6="","",B6/SUM($B$5:$B$14)) -> 0.2 | D6: =IF(A6="","",IFERROR(INDEX('Matérias-Primas'!$D$5:$D$45,MATCH(A6,'Matérias-Primas'!$A$5:$A$45,0)),0)) -> 15 | E6: =IF(A6="",0,C6*IFERROR(INDEX('Matérias-Primas'!$F$5:$F$45,MATCH(A6,'Matérias-Primas'!$A$5:$A$45,0)),0)) -> 9.3 | F6: =IF(A6="",0,C6*IFERROR(INDEX('Matérias-Primas'!$G$5:$G$45,MATCH(A6,'Matérias-Primas'!$A$5:$A$45,0)),0)) -> 0 | G6: =IF(A6="",0,C6*IFERROR(INDEX('Matérias-Primas'!$H$5:$H$45,MATCH(A6,'Matérias-Primas'!$A$5:$A$45,0)),0)) -> 4.62 | H6: =IF(A6="",0,C6*IFERROR(INDEX('Matérias-Primas'!$I$5:$I$45,MATCH(A6,'Matérias-Primas'!$A$5:$A$45,0)),0)) -> 2.06 | I6: =IF(A6="",0,C6*IFERROR(INDEX('Matérias-Primas'!$J$5:$J$45,MATCH(A6,'Matérias-Primas'!$A$5:$A$45,0)),0)) -> 0 | J6: =IF(A6="",0,C6*IFERROR(INDEX('Matérias-Primas'!$K$5:$K$45,MATCH(A6,'Matérias-Primas'!$A$5:$A$45,0)),0)) -> 0 | K6: =IF(A6="",0,C6*IFERROR(INDEX('Matérias-Primas'!$L$5:$L$45,MATCH(A6,'Matérias-Primas'!$A$5:$A$45,0)),0)) -> 4.02 | L6: =IF(A6="",0,C6*IFERROR(INDEX('Matérias-Primas'!$M$5:$M$45,MATCH(A6,'Matérias-Primas'!$A$5:$A$45,0)),0)) -> 0 | M6: =IF(A6="",0,C6*IFERROR(INDEX('Matérias-Primas'!$N$5:$N$45,MATCH(A6,'Matérias-Primas'!$A$5:$A$45,0)),0)) -> 0 | N6: =IF(A6="",0,C6*IFERROR(INDEX('Matérias-Primas'!$O$5:$O$45,MATCH(A6,'Matérias-Primas'!$A$5:$A$45,0)),0)) -> 0 | O6: =IF(A6="",0,C6*IFERROR(INDEX('Matérias-Primas'!$P$5:$P$45,MATCH(A6,'Matérias-Primas'!$A$5:$A$45,0)),0)) -> 0 | P6: =IF(A6="",0,C6*IFERROR(INDEX('Matérias-Primas'!$Q$5:$Q$45,MATCH(A6,'Matérias-Primas'!$A$5:$A$45,0)),0)) -> 0 | Q6: =IF(A6="",0,C6*IFERROR(INDEX('Matérias-Primas'!$R$5:$R$45,MATCH(A6,'Matérias-Primas'!$A$5:$A$45,0)),0)) -> 0
A7: Feldspato potássico | B7: 20 | C7: =IF(B7="","",B7/SUM($B$5:$B$14)) -> 0.2 | D7: =IF(A7="","",IFERROR(INDEX('Matérias-Primas'!$D$5:$D$45,MATCH(A7,'Matérias-Primas'!$A$5:$A$45,0)),0)) -> 3.5 | E7: =IF(A7="",0,C7*IFERROR(INDEX('Matérias-Primas'!$F$5:$F$45,MATCH(A7,'Matérias-Primas'!$A$5:$A$45,0)),0)) -> 13.4 | F7: =IF(A7="",0,C7*IFERROR(INDEX('Matérias-Primas'!$G$5:$G$45,MATCH(A7,'Matérias-Primas'!$A$5:$A$45,0)),0)) -> 3.7 | G7: =IF(A7="",0,C7*IFERROR(INDEX('Matérias-Primas'!$H$5:$H$45,MATCH(A7,'Matérias-Primas'!$A$5:$A$45,0)),0)) -> 0 | H7: =IF(A7="",0,C7*IFERROR(INDEX('Matérias-Primas'!$I$5:$I$45,MATCH(A7,'Matérias-Primas'!$A$5:$A$45,0)),0)) -> 0.6 | I7: =IF(A7="",0,C7*IFERROR(INDEX('Matérias-Primas'!$J$5:$J$45,MATCH(A7,'Matérias-Primas'!$A$5:$A$45,0)),0)) -> 2.2 | J7: =IF(A7="",0,C7*IFERROR(INDEX('Matérias-Primas'!$K$5:$K$45,MATCH(A7,'Matérias-Primas'!$A$5:$A$45,0)),0)) -> 0 | K7: =IF(A7="",0,C7*IFERROR(INDEX('Matérias-Primas'!$L$5:$L$45,MATCH(A7,'Matérias-Primas'!$A$5:$A$45,0)),0)) -> 0.04 | L7: =IF(A7="",0,C7*IFERROR(INDEX('Matérias-Primas'!$M$5:$M$45,MATCH(A7,'Matérias-Primas'!$A$5:$A$45,0)),0)) -> 0 | M7: =IF(A7="",0,C7*IFERROR(INDEX('Matérias-Primas'!$N$5:$N$45,MATCH(A7,'Matérias-Primas'!$A$5:$A$45,0)),0)) -> 0 | N7: =IF(A7="",0,C7*IFERROR(INDEX('Matérias-Primas'!$O$5:$O$45,MATCH(A7,'Matérias-Primas'!$A$5:$A$45,0)),0)) -> 0 | O7: =IF(A7="",0,C7*IFERROR(INDEX('Matérias-Primas'!$P$5:$P$45,MATCH(A7,'Matérias-Primas'!$A$5:$A$45,0)),0)) -> 0 | P7: =IF(A7="",0,C7*IFERROR(INDEX('Matérias-Primas'!$Q$5:$Q$45,MATCH(A7,'Matérias-Primas'!$A$5:$A$45,0)),0)) -> 0.02 | Q7: =IF(A7="",0,C7*IFERROR(INDEX('Matérias-Primas'!$R$5:$R$45,MATCH(A7,'Matérias-Primas'!$A$5:$A$45,0)),0)) -> 0
A8: Caulim | B8: 20 | C8: =IF(B8="","",B8/SUM($B$5:$B$14)) -> 0.2 | D8: =IF(A8="","",IFERROR(INDEX('Matérias-Primas'!$D$5:$D$45,MATCH(A8,'Matérias-Primas'!$A$5:$A$45,0)),0)) -> 2.5 | E8: =IF(A8="",0,C8*IFERROR(INDEX('Matérias-Primas'!$F$5:$F$45,MATCH(A8,'Matérias-Primas'!$A$5:$A$45,0)),0)) -> 9.3 | F8: =IF(A8="",0,C8*IFERROR(INDEX('Matérias-Primas'!$G$5:$G$45,MATCH(A8,'Matérias-Primas'!$A$5:$A$45,0)),0)) -> 7.9 | G8: =IF(A8="",0,C8*IFERROR(INDEX('Matérias-Primas'!$H$5:$H$45,MATCH(A8,'Matérias-Primas'!$A$5:$A$45,0)),0)) -> 0 | H8: =IF(A8="",0,C8*IFERROR(INDEX('Matérias-Primas'!$I$5:$I$45,MATCH(A8,'Matérias-Primas'!$A$5:$A$45,0)),0)) -> 0 | I8: =IF(A8="",0,C8*IFERROR(INDEX('Matérias-Primas'!$J$5:$J$45,MATCH(A8,'Matérias-Primas'!$A$5:$A$45,0)),0)) -> 0 | J8: =IF(A8="",0,C8*IFERROR(INDEX('Matérias-Primas'!$K$5:$K$45,MATCH(A8,'Matérias-Primas'!$A$5:$A$45,0)),0)) -> 0 | K8: =IF(A8="",0,C8*IFERROR(INDEX('Matérias-Primas'!$L$5:$L$45,MATCH(A8,'Matérias-Primas'!$A$5:$A$45,0)),0)) -> 0 | L8: =IF(A8="",0,C8*IFERROR(INDEX('Matérias-Primas'!$M$5:$M$45,MATCH(A8,'Matérias-Primas'!$A$5:$A$45,0)),0)) -> 0 | M8: =IF(A8="",0,C8*IFERROR(INDEX('Matérias-Primas'!$N$5:$N$45,MATCH(A8,'Matérias-Primas'!$A$5:$A$45,0)),0)) -> 0 | N8: =IF(A8="",0,C8*IFERROR(INDEX('Matérias-Primas'!$O$5:$O$45,MATCH(A8,'Matérias-Primas'!$A$5:$A$45,0)),0)) -> 0 | O8: =IF(A8="",0,C8*IFERROR(INDEX('Matérias-Primas'!$P$5:$P$45,MATCH(A8,'Matérias-Primas'!$A$5:$A$45,0)),0)) -> 0 | P8: =IF(A8="",0,C8*IFERROR(INDEX('Matérias-Primas'!$Q$5:$Q$45,MATCH(A8,'Matérias-Primas'!$A$5:$A$45,0)),0)) -> 0.02 | Q8: =IF(A8="",0,C8*IFERROR(INDEX('Matérias-Primas'!$R$5:$R$45,MATCH(A8,'Matérias-Primas'!$A$5:$A$45,0)),0)) -> 0
A9: Quartzo (sílica 325#) | B9: 20 | C9: =IF(B9="","",B9/SUM($B$5:$B$14)) -> 0.2 | D9: =IF(A9="","",IFERROR(INDEX('Matérias-Primas'!$D$5:$D$45,MATCH(A9,'Matérias-Primas'!$A$5:$A$45,0)),0)) -> 2 | E9: =IF(A9="",0,C9*IFERROR(INDEX('Matérias-Primas'!$F$5:$F$45,MATCH(A9,'Matérias-Primas'!$A$5:$A$45,0)),0)) -> 20 | F9: =IF(A9="",0,C9*IFERROR(INDEX('Matérias-Primas'!$G$5:$G$45,MATCH(A9,'Matérias-Primas'!$A$5:$A$45,0)),0)) -> 0 | G9: =IF(A9="",0,C9*IFERROR(INDEX('Matérias-Primas'!$H$5:$H$45,MATCH(A9,'Matérias-Primas'!$A$5:$A$45,0)),0)) -> 0 | H9: =IF(A9="",0,C9*IFERROR(INDEX('Matérias-Primas'!$I$5:$I$45,MATCH(A9,'Matérias-Primas'!$A$5:$A$45,0)),0)) -> 0 | I9: =IF(A9="",0,C9*IFERROR(INDEX('Matérias-Primas'!$J$5:$J$45,MATCH(A9,'Matérias-Primas'!$A$5:$A$45,0)),0)) -> 0 | J9: =IF(A9="",0,C9*IFERROR(INDEX('Matérias-Primas'!$K$5:$K$45,MATCH(A9,'Matérias-Primas'!$A$5:$A$45,0)),0)) -> 0 | K9: =IF(A9="",0,C9*IFERROR(INDEX('Matérias-Primas'!$L$5:$L$45,MATCH(A9,'Matérias-Primas'!$A$5:$A$45,0)),0)) -> 0 | L9: =IF(A9="",0,C9*IFERROR(INDEX('Matérias-Primas'!$M$5:$M$45,MATCH(A9,'Matérias-Primas'!$A$5:$A$45,0)),0)) -> 0 | M9: =IF(A9="",0,C9*IFERROR(INDEX('Matérias-Primas'!$N$5:$N$45,MATCH(A9,'Matérias-Primas'!$A$5:$A$45,0)),0)) -> 0 | N9: =IF(A9="",0,C9*IFERROR(INDEX('Matérias-Primas'!$O$5:$O$45,MATCH(A9,'Matérias-Primas'!$A$5:$A$45,0)),0)) -> 0 | O9: =IF(A9="",0,C9*IFERROR(INDEX('Matérias-Primas'!$P$5:$P$45,MATCH(A9,'Matérias-Primas'!$A$5:$A$45,0)),0)) -> 0 | P9: =IF(A9="",0,C9*IFERROR(INDEX('Matérias-Primas'!$Q$5:$Q$45,MATCH(A9,'Matérias-Primas'!$A$5:$A$45,0)),0)) -> 0 | Q9: =IF(A9="",0,C9*IFERROR(INDEX('Matérias-Primas'!$R$5:$R$45,MATCH(A9,'Matérias-Primas'!$A$5:$A$45,0)),0)) -> 0
C10: =IF(B10="","",B10/SUM($B$5:$B$14)) | D10: =IF(A10="","",IFERROR(INDEX('Matérias-Primas'!$D$5:$D$45,MATCH(A10,'Matérias-Primas'!$A$5:$A$45,0)),0)) | E10: =IF(A10="",0,C10*IFERROR(INDEX('Matérias-Primas'!$F$5:$F$45,MATCH(A10,'Matérias-Primas'!$A$5:$A$45,0)),0)) -> 0 | F10: =IF(A10="",0,C10*IFERROR(INDEX('Matérias-Primas'!$G$5:$G$45,MATCH(A10,'Matérias-Primas'!$A$5:$A$45,0)),0)) -> 0 | G10: =IF(A10="",0,C10*IFERROR(INDEX('Matérias-Primas'!$H$5:$H$45,MATCH(A10,'Matérias-Primas'!$A$5:$A$45,0)),0)) -> 0 | H10: =IF(A10="",0,C10*IFERROR(INDEX('Matérias-Primas'!$I$5:$I$45,MATCH(A10,'Matérias-Primas'!$A$5:$A$45,0)),0)) -> 0 | I10: =IF(A10="",0,C10*IFERROR(INDEX('Matérias-Primas'!$J$5:$J$45,MATCH(A10,'Matérias-Primas'!$A$5:$A$45,0)),0)) -> 0 | J10: =IF(A10="",0,C10*IFERROR(INDEX('Matérias-Primas'!$K$5:$K$45,MATCH(A10,'Matérias-Primas'!$A$5:$A$45,0)),0)) -> 0 | K10: =IF(A10="",0,C10*IFERROR(INDEX('Matérias-Primas'!$L$5:$L$45,MATCH(A10,'Matérias-Primas'!$A$5:$A$45,0)),0)) -> 0 | L10: =IF(A10="",0,C10*IFERROR(INDEX('Matérias-Primas'!$M$5:$M$45,MATCH(A10,'Matérias-Primas'!$A$5:$A$45,0)),0)) -> 0 | M10: =IF(A10="",0,C10*IFERROR(INDEX('Matérias-Primas'!$N$5:$N$45,MATCH(A10,'Matérias-Primas'!$A$5:$A$45,0)),0)) -> 0 | N10: =IF(A10="",0,C10*IFERROR(INDEX('Matérias-Primas'!$O$5:$O$45,MATCH(A10,'Matérias-Primas'!$A$5:$A$45,0)),0)) -> 0 | O10: =IF(A10="",0,C10*IFERROR(INDEX('Matérias-Primas'!$P$5:$P$45,MATCH(A10,'Matérias-Primas'!$A$5:$A$45,0)),0)) -> 0 | P10: =IF(A10="",0,C10*IFERROR(INDEX('Matérias-Primas'!$Q$5:$Q$45,MATCH(A10,'Matérias-Primas'!$A$5:$A$45,0)),0)) -> 0 | Q10: =IF(A10="",0,C10*IFERROR(INDEX('Matérias-Primas'!$R$5:$R$45,MATCH(A10,'Matérias-Primas'!$A$5:$A$45,0)),0)) -> 0
C11: =IF(B11="","",B11/SUM($B$5:$B$14)) | D11: =IF(A11="","",IFERROR(INDEX('Matérias-Primas'!$D$5:$D$45,MATCH(A11,'Matérias-Primas'!$A$5:$A$45,0)),0)) | E11: =IF(A11="",0,C11*IFERROR(INDEX('Matérias-Primas'!$F$5:$F$45,MATCH(A11,'Matérias-Primas'!$A$5:$A$45,0)),0)) -> 0 | F11: =IF(A11="",0,C11*IFERROR(INDEX('Matérias-Primas'!$G$5:$G$45,MATCH(A11,'Matérias-Primas'!$A$5:$A$45,0)),0)) -> 0 | G11: =IF(A11="",0,C11*IFERROR(INDEX('Matérias-Primas'!$H$5:$H$45,MATCH(A11,'Matérias-Primas'!$A$5:$A$45,0)),0)) -> 0 | H11: =IF(A11="",0,C11*IFERROR(INDEX('Matérias-Primas'!$I$5:$I$45,MATCH(A11,'Matérias-Primas'!$A$5:$A$45,0)),0)) -> 0 | I11: =IF(A11="",0,C11*IFERROR(INDEX('Matérias-Primas'!$J$5:$J$45,MATCH(A11,'Matérias-Primas'!$A$5:$A$45,0)),0)) -> 0 | J11: =IF(A11="",0,C11*IFERROR(INDEX('Matérias-Primas'!$K$5:$K$45,MATCH(A11,'Matérias-Primas'!$A$5:$A$45,0)),0)) -> 0 | K11: =IF(A11="",0,C11*IFERROR(INDEX('Matérias-Primas'!$L$5:$L$45,MATCH(A11,'Matérias-Primas'!$A$5:$A$45,0)),0)) -> 0 | L11: =IF(A11="",0,C11*IFERROR(INDEX('Matérias-Primas'!$M$5:$M$45,MATCH(A11,'Matérias-Primas'!$A$5:$A$45,0)),0)) -> 0 | M11: =IF(A11="",0,C11*IFERROR(INDEX('Matérias-Primas'!$N$5:$N$45,MATCH(A11,'Matérias-Primas'!$A$5:$A$45,0)),0)) -> 0 | N11: =IF(A11="",0,C11*IFERROR(INDEX('Matérias-Primas'!$O$5:$O$45,MATCH(A11,'Matérias-Primas'!$A$5:$A$45,0)),0)) -> 0 | O11: =IF(A11="",0,C11*IFERROR(INDEX('Matérias-Primas'!$P$5:$P$45,MATCH(A11,'Matérias-Primas'!$A$5:$A$45,0)),0)) -> 0 | P11: =IF(A11="",0,C11*IFERROR(INDEX('Matérias-Primas'!$Q$5:$Q$45,MATCH(A11,'Matérias-Primas'!$A$5:$A$45,0)),0)) -> 0 | Q11: =IF(A11="",0,C11*IFERROR(INDEX('Matérias-Primas'!$R$5:$R$45,MATCH(A11,'Matérias-Primas'!$A$5:$A$45,0)),0)) -> 0
C12: =IF(B12="","",B12/SUM($B$5:$B$14)) | D12: =IF(A12="","",IFERROR(INDEX('Matérias-Primas'!$D$5:$D$45,MATCH(A12,'Matérias-Primas'!$A$5:$A$45,0)),0)) | E12: =IF(A12="",0,C12*IFERROR(INDEX('Matérias-Primas'!$F$5:$F$45,MATCH(A12,'Matérias-Primas'!$A$5:$A$45,0)),0)) -> 0 | F12: =IF(A12="",0,C12*IFERROR(INDEX('Matérias-Primas'!$G$5:$G$45,MATCH(A12,'Matérias-Primas'!$A$5:$A$45,0)),0)) -> 0 | G12: =IF(A12="",0,C12*IFERROR(INDEX('Matérias-Primas'!$H$5:$H$45,MATCH(A12,'Matérias-Primas'!$A$5:$A$45,0)),0)) -> 0 | H12: =IF(A12="",0,C12*IFERROR(INDEX('Matérias-Primas'!$I$5:$I$45,MATCH(A12,'Matérias-Primas'!$A$5:$A$45,0)),0)) -> 0 | I12: =IF(A12="",0,C12*IFERROR(INDEX('Matérias-Primas'!$J$5:$J$45,MATCH(A12,'Matérias-Primas'!$A$5:$A$45,0)),0)) -> 0 | J12: =IF(A12="",0,C12*IFERROR(INDEX('Matérias-Primas'!$K$5:$K$45,MATCH(A12,'Matérias-Primas'!$A$5:$A$45,0)),0)) -> 0 | K12: =IF(A12="",0,C12*IFERROR(INDEX('Matérias-Primas'!$L$5:$L$45,MATCH(A12,'Matérias-Primas'!$A$5:$A$45,0)),0)) -> 0 | L12: =IF(A12="",0,C12*IFERROR(INDEX('Matérias-Primas'!$M$5:$M$45,MATCH(A12,'Matérias-Primas'!$A$5:$A$45,0)),0)) -> 0 | M12: =IF(A12="",0,C12*IFERROR(INDEX('Matérias-Primas'!$N$5:$N$45,MATCH(A12,'Matérias-Primas'!$A$5:$A$45,0)),0)) -> 0 | N12: =IF(A12="",0,C12*IFERROR(INDEX('Matérias-Primas'!$O$5:$O$45,MATCH(A12,'Matérias-Primas'!$A$5:$A$45,0)),0)) -> 0 | O12: =IF(A12="",0,C12*IFERROR(INDEX('Matérias-Primas'!$P$5:$P$45,MATCH(A12,'Matérias-Primas'!$A$5:$A$45,0)),0)) -> 0 | P12: =IF(A12="",0,C12*IFERROR(INDEX('Matérias-Primas'!$Q$5:$Q$45,MATCH(A12,'Matérias-Primas'!$A$5:$A$45,0)),0)) -> 0 | Q12: =IF(A12="",0,C12*IFERROR(INDEX('Matérias-Primas'!$R$5:$R$45,MATCH(A12,'Matérias-Primas'!$A$5:$A$45,0)),0)) -> 0
C13: =IF(B13="","",B13/SUM($B$5:$B$14)) | D13: =IF(A13="","",IFERROR(INDEX('Matérias-Primas'!$D$5:$D$45,MATCH(A13,'Matérias-Primas'!$A$5:$A$45,0)),0)) | E13: =IF(A13="",0,C13*IFERROR(INDEX('Matérias-Primas'!$F$5:$F$45,MATCH(A13,'Matérias-Primas'!$A$5:$A$45,0)),0)) -> 0 | F13: =IF(A13="",0,C13*IFERROR(INDEX('Matérias-Primas'!$G$5:$G$45,MATCH(A13,'Matérias-Primas'!$A$5:$A$45,0)),0)) -> 0 | G13: =IF(A13="",0,C13*IFERROR(INDEX('Matérias-Primas'!$H$5:$H$45,MATCH(A13,'Matérias-Primas'!$A$5:$A$45,0)),0)) -> 0 | H13: =IF(A13="",0,C13*IFERROR(INDEX('Matérias-Primas'!$I$5:$I$45,MATCH(A13,'Matérias-Primas'!$A$5:$A$45,0)),0)) -> 0 | I13: =IF(A13="",0,C13*IFERROR(INDEX('Matérias-Primas'!$J$5:$J$45,MATCH(A13,'Matérias-Primas'!$A$5:$A$45,0)),0)) -> 0 | J13: =IF(A13="",0,C13*IFERROR(INDEX('Matérias-Primas'!$K$5:$K$45,MATCH(A13,'Matérias-Primas'!$A$5:$A$45,0)),0)) -> 0 | K13: =IF(A13="",0,C13*IFERROR(INDEX('Matérias-Primas'!$L$5:$L$45,MATCH(A13,'Matérias-Primas'!$A$5:$A$45,0)),0)) -> 0 | L13: =IF(A13="",0,C13*IFERROR(INDEX('Matérias-Primas'!$M$5:$M$45,MATCH(A13,'Matérias-Primas'!$A$5:$A$45,0)),0)) -> 0 | M13: =IF(A13="",0,C13*IFERROR(INDEX('Matérias-Primas'!$N$5:$N$45,MATCH(A13,'Matérias-Primas'!$A$5:$A$45,0)),0)) -> 0 | N13: =IF(A13="",0,C13*IFERROR(INDEX('Matérias-Primas'!$O$5:$O$45,MATCH(A13,'Matérias-Primas'!$A$5:$A$45,0)),0)) -> 0 | O13: =IF(A13="",0,C13*IFERROR(INDEX('Matérias-Primas'!$P$5:$P$45,MATCH(A13,'Matérias-Primas'!$A$5:$A$45,0)),0)) -> 0 | P13: =IF(A13="",0,C13*IFERROR(INDEX('Matérias-Primas'!$Q$5:$Q$45,MATCH(A13,'Matérias-Primas'!$A$5:$A$45,0)),0)) -> 0 | Q13: =IF(A13="",0,C13*IFERROR(INDEX('Matérias-Primas'!$R$5:$R$45,MATCH(A13,'Matérias-Primas'!$A$5:$A$45,0)),0)) -> 0
C14: =IF(B14="","",B14/SUM($B$5:$B$14)) | D14: =IF(A14="","",IFERROR(INDEX('Matérias-Primas'!$D$5:$D$45,MATCH(A14,'Matérias-Primas'!$A$5:$A$45,0)),0)) | E14: =IF(A14="",0,C14*IFERROR(INDEX('Matérias-Primas'!$F$5:$F$45,MATCH(A14,'Matérias-Primas'!$A$5:$A$45,0)),0)) -> 0 | F14: =IF(A14="",0,C14*IFERROR(INDEX('Matérias-Primas'!$G$5:$G$45,MATCH(A14,'Matérias-Primas'!$A$5:$A$45,0)),0)) -> 0 | G14: =IF(A14="",0,C14*IFERROR(INDEX('Matérias-Primas'!$H$5:$H$45,MATCH(A14,'Matérias-Primas'!$A$5:$A$45,0)),0)) -> 0 | H14: =IF(A14="",0,C14*IFERROR(INDEX('Matérias-Primas'!$I$5:$I$45,MATCH(A14,'Matérias-Primas'!$A$5:$A$45,0)),0)) -> 0 | I14: =IF(A14="",0,C14*IFERROR(INDEX('Matérias-Primas'!$J$5:$J$45,MATCH(A14,'Matérias-Primas'!$A$5:$A$45,0)),0)) -> 0 | J14: =IF(A14="",0,C14*IFERROR(INDEX('Matérias-Primas'!$K$5:$K$45,MATCH(A14,'Matérias-Primas'!$A$5:$A$45,0)),0)) -> 0 | K14: =IF(A14="",0,C14*IFERROR(INDEX('Matérias-Primas'!$L$5:$L$45,MATCH(A14,'Matérias-Primas'!$A$5:$A$45,0)),0)) -> 0 | L14: =IF(A14="",0,C14*IFERROR(INDEX('Matérias-Primas'!$M$5:$M$45,MATCH(A14,'Matérias-Primas'!$A$5:$A$45,0)),0)) -> 0 | M14: =IF(A14="",0,C14*IFERROR(INDEX('Matérias-Primas'!$N$5:$N$45,MATCH(A14,'Matérias-Primas'!$A$5:$A$45,0)),0)) -> 0 | N14: =IF(A14="",0,C14*IFERROR(INDEX('Matérias-Primas'!$O$5:$O$45,MATCH(A14,'Matérias-Primas'!$A$5:$A$45,0)),0)) -> 0 | O14: =IF(A14="",0,C14*IFERROR(INDEX('Matérias-Primas'!$P$5:$P$45,MATCH(A14,'Matérias-Primas'!$A$5:$A$45,0)),0)) -> 0 | P14: =IF(A14="",0,C14*IFERROR(INDEX('Matérias-Primas'!$Q$5:$Q$45,MATCH(A14,'Matérias-Primas'!$A$5:$A$45,0)),0)) -> 0 | Q14: =IF(A14="",0,C14*IFERROR(INDEX('Matérias-Primas'!$R$5:$R$45,MATCH(A14,'Matérias-Primas'!$A$5:$A$45,0)),0)) -> 0
A15: Total | B15: =SUM(B5:B14) -> 100 | C15: =SUM(C5:C14) -> 1 | E15: =SUM(E5:E14) -> 62.34 | F15: =SUM(F5:F14) -> 11.6 | G15: =SUM(G5:G14) -> 4.62 | H15: =SUM(H5:H14) -> 2.66 | I15: =SUM(I5:I14) -> 2.2 | J15: =SUM(J5:J14) -> 0 | K15: =SUM(K5:K14) -> 13.72 | L15: =SUM(L5:L14) -> 0 | ... Q15: =SUM(Q5:Q14) -> 0
A16: Massa molar | E16: ='Matérias-Primas'!F3 -> 60.08 | F16: ='Matérias-Primas'!G3 -> 101.96 | G16: ='Matérias-Primas'!H3 -> 69.62 | H16: ='Matérias-Primas'!I3 -> 61.98 | I16: ='Matérias-Primas'!J3 -> 94.2 | J16: ='Matérias-Primas'!K3 -> 29.88 | K16: ='Matérias-Primas'!L3 -> 56.08 | L16: ='Matérias-Primas'!M3 -> 40.3 | ... Q16: ='Matérias-Primas'!R3 -> 79.87
A17: Mols | C17: Soma fundentes: | D17: =H17+I17+J17+K17+L17+M17+N17 -> 0.31092213 | E17: =E15/E16 -> 1.0376165 | F17: =F15/F16 -> 0.11377011 | G17: =G15/G16 -> 0.066360241 | H17: =H15/H16 -> 0.04291707 | I17: =I15/I16 -> 0.023354565 | J17: =J15/J16 -> 0 | K17: =K15/K16 -> 0.2446505 | L17: =L15/L16 -> 0 | ... Q17: =Q15/Q16 -> 0
A18: UMF (fundentes = 1) | E18: =IF($D$17=0,0,E17/$D$17) -> 3.337223 | F18: =IF($D$17=0,0,F17/$D$17) -> 0.36591189 | G18: =IF($D$17=0,0,G17/$D$17) -> 0.21343042 | H18: =IF($D$17=0,0,H17/$D$17) -> 0.13803157 | I18: =IF($D$17=0,0,I17/$D$17) -> 0.07511387 | J18: =IF($D$17=0,0,J17/$D$17) -> 0 | K18: =IF($D$17=0,0,K17/$D$17) -> 0.78685456 | L18: =IF($D$17=0,0,L17/$D$17) -> 0 | ... Q18: =IF($D$17=0,0,Q17/$D$17) -> 0
A20: Checagem contra faixas-alvo
A21: Indicador | B21: Valor | C21: Mín | D21: Máx | E21: Status
A22: SiO₂ (UMF) | B22: =E18 -> 3.337223 | C22: 3 | D22: 4 | E22: =IF(AND(B22>=C22,B22<=D22),"OK","Ajustar") -> OK
A23: Al₂O₃ (UMF) | B23: =F18 -> 0.36591189 | C23: 0.3 | D23: 0.4 | E23: =IF(AND(B23>=C23,B23<=D23),"OK","Ajustar") -> OK
A24: B₂O₃ (UMF) | B24: =G18 -> 0.21343042 | C24: 0.1 | D24: 0.3 | E24: =IF(AND(B24>=C24,B24<=D24),"OK","Ajustar") -> OK
A25: Razão SiO₂:Al₂O₃ | B25: =IF(F18=0,0,E18/F18) -> 9.1202913 | C25: 8 | D25: 10 | E25: =IF(AND(B25>=C25,B25<=D25),"OK","Ajustar") -> OK
A27: Custo matéria-prima da base (R$/kg) | B27: =SUMPRODUCT(C5:C14,D5:D14) -> 6.2
A28: Faixas-alvo são referências de literatura para cone 6 estável; ajuste-as conforme seus testes. Fórmula-alvo calculada sobre óxidos; colorantes entram na aba Cores.

Sheet Base B
A1: Base B — Mate/acetinada cálcica (sem zinco)
A2: Mate por alumina alta + cálcio. Sem zinco para permitir o rosa cromo-estanho.
E3: Contribuição em massa de cada óxido (g por 100 g de esmalte queimado não normalizado) →
A4: Material | B4: Quantidade (g) | C4: % normalizado | D4: Preço (R$/kg) | E4: SiO2 | F4: Al2O3 | G4: B2O3 | H4: Na2O | I4: K2O | J4: Li2O | K4: CaO | L4: MgO | M4: SrO | N4: ZnO | O4: ZrO2 | P4: Fe2O3 | Q4: TiO2
A5: Feldspato potássico | B5: 30 | C5: =IF(B5="","",B5/SUM($B$5:$B$14)) -> 0.3 | D5: =IF(A5="","",IFERROR(INDEX('Matérias-Primas'!$D$5:$D$45,MATCH(A5,'Matérias-Primas'!$A$5:$A$45,0)),0)) -> 3.5 | E5: =IF(A5="",0,C5*IFERROR(INDEX('Matérias-Primas'!$F$5:$F$45,MATCH(A5,'Matérias-Primas'!$A$5:$A$45,0)),0)) -> 20.1 | F5: =IF(A5="",0,C5*IFERROR(INDEX('Matérias-Primas'!$G$5:$G$45,MATCH(A5,'Matérias-Primas'!$A$5:$A$45,0)),0)) -> 5.55 | G5: =IF(A5="",0,C5*IFERROR(INDEX('Matérias-Primas'!$H$5:$H$45,MATCH(A5,'Matérias-Primas'!$A$5:$A$45,0)),0)) -> 0 | H5: =IF(A5="",0,C5*IFERROR(INDEX('Matérias-Primas'!$I$5:$I$45,MATCH(A5,'Matérias-Primas'!$A$5:$A$45,0)),0)) -> 0.9 | I5: =IF(A5="",0,C5*IFERROR(INDEX('Matérias-Primas'!$J$5:$J$45,MATCH(A5,'Matérias-Primas'!$A$5:$A$45,0)),0)) -> 3.3 | J5: =IF(A5="",0,C5*IFERROR(INDEX('Matérias-Primas'!$K$5:$K$45,MATCH(A5,'Matérias-Primas'!$A$5:$A$45,0)),0)) -> 0 | K5: =IF(A5="",0,C5*IFERROR(INDEX('Matérias-Primas'!$L$5:$L$45,MATCH(A5,'Matérias-Primas'!$A$5:$A$45,0)),0)) -> 0.06 | L5: =IF(A5="",0,C5*IFERROR(INDEX('Matérias-Primas'!$M$5:$M$45,MATCH(A5,'Matérias-Primas'!$A$5:$A$45,0)),0)) -> 0 | M5: =IF(A5="",0,C5*IFERROR(INDEX('Matérias-Primas'!$N$5:$N$45,MATCH(A5,'Matérias-Primas'!$A$5:$A$45,0)),0)) -> 0 | N5: =IF(A5="",0,C5*IFERROR(INDEX('Matérias-Primas'!$O$5:$O$45,MATCH(A5,'Matérias-Primas'!$A$5:$A$45,0)),0)) -> 0 | O5: =IF(A5="",0,C5*IFERROR(INDEX('Matérias-Primas'!$P$5:$P$45,MATCH(A5,'Matérias-Primas'!$A$5:$A$45,0)),0)) -> 0 | P5: =IF(A5="",0,C5*IFERROR(INDEX('Matérias-Primas'!$Q$5:$Q$45,MATCH(A5,'Matérias-Primas'!$A$5:$A$45,0)),0)) -> 0.03 | Q5: =IF(A5="",0,C5*IFERROR(INDEX('Matérias-Primas'!$R$5:$R$45,MATCH(A5,'Matérias-Primas'!$A$5:$A$45,0)),0)) -> 0
A6: Frita borácica | B6: 12 | C6: =IF(B6="","",B6/SUM($B$5:$B$14)) -> 0.12 | D6: =IF(A6="","",IFERROR(INDEX('Matérias-Primas'!$D$5:$D$45,MATCH(A6,'Matérias-Primas'!$A$5:$A$45,0)),0)) -> 15 | E6: =IF(A6="",0,C6*IFERROR(INDEX('Matérias-Primas'!$F$5:$F$45,MATCH(A6,'Matérias-Primas'!$A$5:$A$45,0)),0)) -> 5.58 | F6: =IF(A6="",0,C6*IFERROR(INDEX('Matérias-Primas'!$G$5:$G$45,MATCH(A6,'Matérias-Primas'!$A$5:$A$45,0)),0)) -> 0 | G6: =IF(A6="",0,C6*IFERROR(INDEX('Matérias-Primas'!$H$5:$H$45,MATCH(A6,'Matérias-Primas'!$A$5:$A$45,0)),0)) -> 2.772 | H6: =IF(A6="",0,C6*IFERROR(INDEX('Matérias-Primas'!$I$5:$I$45,MATCH(A6,'Matérias-Primas'!$A$5:$A$45,0)),0)) -> 1.236 | I6: =IF(A6="",0,C6*IFERROR(INDEX('Matérias-Primas'!$J$5:$J$45,MATCH(A6,'Matérias-Primas'!$A$5:$A$45,0)),0)) -> 0 | J6: =IF(A6="",0,C6*IFERROR(INDEX('Matérias-Primas'!$K$5:$K$45,MATCH(A6,'Matérias-Primas'!$A$5:$A$45,0)),0)) -> 0 | K6: =IF(A6="",0,C6*IFERROR(INDEX('Matérias-Primas'!$L$5:$L$45,MATCH(A6,'Matérias-Primas'!$A$5:$A$45,0)),0)) -> 2.412 | L6: =IF(A6="",0,C6*IFERROR(INDEX('Matérias-Primas'!$M$5:$M$45,MATCH(A6,'Matérias-Primas'!$A$5:$A$45,0)),0)) -> 0 | M6: =IF(A6="",0,C6*IFERROR(INDEX('Matérias-Primas'!$N$5:$N$45,MATCH(A6,'Matérias-Primas'!$A$5:$A$45,0)),0)) -> 0 | N6: =IF(A6="",0,C6*IFERROR(INDEX('Matérias-Primas'!$O$5:$O$45,MATCH(A6,'Matérias-Primas'!$A$5:$A$45,0)),0)) -> 0 | O6: =IF(A6="",0,C6*IFERROR(INDEX('Matérias-Primas'!$P$5:$P$45,MATCH(A6,'Matérias-Primas'!$A$5:$A$45,0)),0)) -> 0 | P6: =IF(A6="",0,C6*IFERROR(INDEX('Matérias-Primas'!$Q$5:$Q$45,MATCH(A6,'Matérias-Primas'!$A$5:$A$45,0)),0)) -> 0 | Q6: =IF(A6="",0,C6*IFERROR(INDEX('Matérias-Primas'!$R$5:$R$45,MATCH(A6,'Matérias-Primas'!$A$5:$A$45,0)),0)) -> 0
A7: Wollastonita | B7: 22 | C7: =IF(B7="","",B7/SUM($B$5:$B$14)) -> 0.22 | D7: =IF(A7="","",IFERROR(INDEX('Matérias-Primas'!$D$5:$D$45,MATCH(A7,'Matérias-Primas'!$A$5:$A$45,0)),0)) -> 8 | E7: =IF(A7="",0,C7*IFERROR(INDEX('Matérias-Primas'!$F$5:$F$45,MATCH(A7,'Matérias-Primas'!$A$5:$A$45,0)),0)) -> 11.374 | F7: =IF(A7="",0,C7*IFERROR(INDEX('Matérias-Primas'!$G$5:$G$45,MATCH(A7,'Matérias-Primas'!$A$5:$A$45,0)),0)) -> 0 | G7: =IF(A7="",0,C7*IFERROR(INDEX('Matérias-Primas'!$H$5:$H$45,MATCH(A7,'Matérias-Primas'!$A$5:$A$45,0)),0)) -> 0 | H7: =IF(A7="",0,C7*IFERROR(INDEX('Matérias-Primas'!$I$5:$I$45,MATCH(A7,'Matérias-Primas'!$A$5:$A$45,0)),0)) -> 0 | I7: =IF(A7="",0,C7*IFERROR(INDEX('Matérias-Primas'!$J$5:$J$45,MATCH(A7,'Matérias-Primas'!$A$5:$A$45,0)),0)) -> 0 | J7: =IF(A7="",0,C7*IFERROR(INDEX('Matérias-Primas'!$K$5:$K$45,MATCH(A7,'Matérias-Primas'!$A$5:$A$45,0)),0)) -> 0 | K7: =IF(A7="",0,C7*IFERROR(INDEX('Matérias-Primas'!$L$5:$L$45,MATCH(A7,'Matérias-Primas'!$A$5:$A$45,0)),0)) -> 10.626 | L7: =IF(A7="",0,C7*IFERROR(INDEX('Matérias-Primas'!$M$5:$M$45,MATCH(A7,'Matérias-Primas'!$A$5:$A$45,0)),0)) -> 0 | M7: =IF(A7="",0,C7*IFERROR(INDEX('Matérias-Primas'!$N$5:$N$45,MATCH(A7,'Matérias-Primas'!$A$5:$A$45,0)),0)) -> 0 | N7: =IF(A7="",0,C7*IFERROR(INDEX('Matérias-Primas'!$O$5:$O$45,MATCH(A7,'Matérias-Primas'!$A$5:$A$45,0)),0)) -> 0 | O7: =IF(A7="",0,C7*IFERROR(INDEX('Matérias-Primas'!$P$5:$P$45,MATCH(A7,'Matérias-Primas'!$A$5:$A$45,0)),0)) -> 0 | P7: =IF(A7="",0,C7*IFERROR(INDEX('Matérias-Primas'!$Q$5:$Q$45,MATCH(A7,'Matérias-Primas'!$A$5:$A$45,0)),0)) -> 0 | Q7: =IF(A7="",0,C7*IFERROR(INDEX('Matérias-Primas'!$R$5:$R$45,MATCH(A7,'Matérias-Primas'!$A$5:$A$45,0)),0)) -> 0
A8: Carbonato de cálcio | B8: 6 | C8: =IF(B8="","",B8/SUM($B$5:$B$14)) -> 0.06 | D8: =IF(A8="","",IFERROR(INDEX('Matérias-Primas'!$D$5:$D$45,MATCH(A8,'Matérias-Primas'!$A$5:$A$45,0)),0)) -> 2 | E8: =IF(A8="",0,C8*IFERROR(INDEX('Matérias-Primas'!$F$5:$F$45,MATCH(A8,'Matérias-Primas'!$A$5:$A$45,0)),0)) -> 0 | F8: =IF(A8="",0,C8*IFERROR(INDEX('Matérias-Primas'!$G$5:$G$45,MATCH(A8,'Matérias-Primas'!$A$5:$A$45,0)),0)) -> 0 | G8: =IF(A8="",0,C8*IFERROR(INDEX('Matérias-Primas'!$H$5:$H$45,MATCH(A8,'Matérias-Primas'!$A$5:$A$45,0)),0)) -> 0 | H8: =IF(A8="",0,C8*IFERROR(INDEX('Matérias-Primas'!$I$5:$I$45,MATCH(A8,'Matérias-Primas'!$A$5:$A$45,0)),0)) -> 0 | I8: =IF(A8="",0,C8*IFERROR(INDEX('Matérias-Primas'!$J$5:$J$45,MATCH(A8,'Matérias-Primas'!$A$5:$A$45,0)),0)) -> 0 | J8: =IF(A8="",0,C8*IFERROR(INDEX('Matérias-Primas'!$K$5:$K$45,MATCH(A8,'Matérias-Primas'!$A$5:$A$45,0)),0)) -> 0 | K8: =IF(A8="",0,C8*IFERROR(INDEX('Matérias-Primas'!$L$5:$L$45,MATCH(A8,'Matérias-Primas'!$A$5:$A$45,0)),0)) -> 3.36 | L8: =IF(A8="",0,C8*IFERROR(INDEX('Matérias-Primas'!$M$5:$M$45,MATCH(A8,'Matérias-Primas'!$A$5:$A$45,0)),0)) -> 0 | M8: =IF(A8="",0,C8*IFERROR(INDEX('Matérias-Primas'!$N$5:$N$45,MATCH(A8,'Matérias-Primas'!$A$5:$A$45,0)),0)) -> 0 | N8: =IF(A8="",0,C8*IFERROR(INDEX('Matérias-Primas'!$O$5:$O$45,MATCH(A8,'Matérias-Primas'!$A$5:$A$45,0)),0)) -> 0 | O8: =IF(A8="",0,C8*IFERROR(INDEX('Matérias-Primas'!$P$5:$P$45,MATCH(A8,'Matérias-Primas'!$A$5:$A$45,0)),0)) -> 0 | P8: =IF(A8="",0,C8*IFERROR(INDEX('Matérias-Primas'!$Q$5:$Q$45,MATCH(A8,'Matérias-Primas'!$A$5:$A$45,0)),0)) -> 0 | Q8: =IF(A8="",0,C8*IFERROR(INDEX('Matérias-Primas'!$R$5:$R$45,MATCH(A8,'Matérias-Primas'!$A$5:$A$45,0)),0)) -> 0
A9: Caulim | B9: 25 | C9: =IF(B9="","",B9/SUM($B$5:$B$14)) -> 0.25 | D9: =IF(A9="","",IFERROR(INDEX('Matérias-Primas'!$D$5:$D$45,MATCH(A9,'Matérias-Primas'!$A$5:$A$45,0)),0)) -> 2.5 | E9: =IF(A9="",0,C9*IFERROR(INDEX('Matérias-Primas'!$F$5:$F$45,MATCH(A9,'Matérias-Primas'!$A$5:$A$45,0)),0)) -> 11.625 | F9: =IF(A9="",0,C9*IFERROR(INDEX('Matérias-Primas'!$G$5:$G$45,MATCH(A9,'Matérias-Primas'!$A$5:$A$45,0)),0)) -> 9.875 | G9: =IF(A9="",0,C9*IFERROR(INDEX('Matérias-Primas'!$H$5:$H$45,MATCH(A9,'Matérias-Primas'!$A$5:$A$45,0)),0)) -> 0 | H9: =IF(A9="",0,C9*IFERROR(INDEX('Matérias-Primas'!$I$5:$I$45,MATCH(A9,'Matérias-Primas'!$A$5:$A$45,0)),0)) -> 0 | I9: =IF(A9="",0,C9*IFERROR(INDEX('Matérias-Primas'!$J$5:$J$45,MATCH(A9,'Matérias-Primas'!$A$5:$A$45,0)),0)) -> 0 | J9: =IF(A9="",0,C9*IFERROR(INDEX('Matérias-Primas'!$K$5:$K$45,MATCH(A9,'Matérias-Primas'!$A$5:$A$45,0)),0)) -> 0 | K9: =IF(A9="",0,C9*IFERROR(INDEX('Matérias-Primas'!$L$5:$L$45,MATCH(A9,'Matérias-Primas'!$A$5:$A$45,0)),0)) -> 0 | L9: =IF(A9="",0,C9*IFERROR(INDEX('Matérias-Primas'!$M$5:$M$45,MATCH(A9,'Matérias-Primas'!$A$5:$A$45,0)),0)) -> 0 | M9: =IF(A9="",0,C9*IFERROR(INDEX('Matérias-Primas'!$N$5:$N$45,MATCH(A9,'Matérias-Primas'!$A$5:$A$45,0)),0)) -> 0 | N9: =IF(A9="",0,C9*IFERROR(INDEX('Matérias-Primas'!$O$5:$O$45,MATCH(A9,'Matérias-Primas'!$A$5:$A$45,0)),0)) -> 0 | O9: =IF(A9="",0,C9*IFERROR(INDEX('Matérias-Primas'!$P$5:$P$45,MATCH(A9,'Matérias-Primas'!$A$5:$A$45,0)),0)) -> 0 | P9: =IF(A9="",0,C9*IFERROR(INDEX('Matérias-Primas'!$Q$5:$Q$45,MATCH(A9,'Matérias-Primas'!$A$5:$A$45,0)),0)) -> 0.025 | Q9: =IF(A9="",0,C9*IFERROR(INDEX('Matérias-Primas'!$R$5:$R$45,MATCH(A9,'Matérias-Primas'!$A$5:$A$45,0)),0)) -> 0
A10: Quartzo (sílica 325#) | B10: 5 | C10: =IF(B10="","",B10/SUM($B$5:$B$14)) -> 0.05 | D10: =IF(A10="","",IFERROR(INDEX('Matérias-Primas'!$D$5:$D$45,MATCH(A10,'Matérias-Primas'!$A$5:$A$45,0)),0)) -> 2 | E10: =IF(A10="",0,C10*IFERROR(INDEX('Matérias-Primas'!$F$5:$F$45,MATCH(A10,'Matérias-Primas'!$A$5:$A$45,0)),0)) -> 5 | F10: =IF(A10="",0,C10*IFERROR(INDEX('Matérias-Primas'!$G$5:$G$45,MATCH(A10,'Matérias-Primas'!$A$5:$A$45,0)),0)) -> 0 | G10: =IF(A10="",0,C10*IFERROR(INDEX('Matérias-Primas'!$H$5:$H$45,MATCH(A10,'Matérias-Primas'!$A$5:$A$45,0)),0)) -> 0 | H10: =IF(A10="",0,C10*IFERROR(INDEX('Matérias-Primas'!$I$5:$I$45,MATCH(A10,'Matérias-Primas'!$A$5:$A$45,0)),0)) -> 0 | I10: =IF(A10="",0,C10*IFERROR(INDEX('Matérias-Primas'!$J$5:$J$45,MATCH(A10,'Matérias-Primas'!$A$5:$A$45,0)),0)) -> 0 | J10: =IF(A10="",0,C10*IFERROR(INDEX('Matérias-Primas'!$K$5:$K$45,MATCH(A10,'Matérias-Primas'!$A$5:$A$45,0)),0)) -> 0 | K10: =IF(A10="",0,C10*IFERROR(INDEX('Matérias-Primas'!$L$5:$L$45,MATCH(A10,'Matérias-Primas'!$A$5:$A$45,0)),0)) -> 0 | L10: =IF(A10="",0,C10*IFERROR(INDEX('Matérias-Primas'!$M$5:$M$45,MATCH(A10,'Matérias-Primas'!$A$5:$A$45,0)),0)) -> 0 | M10: =IF(A10="",0,C10*IFERROR(INDEX('Matérias-Primas'!$N$5:$N$45,MATCH(A10,'Matérias-Primas'!$A$5:$A$45,0)),0)) -> 0 | N10: =IF(A10="",0,C10*IFERROR(INDEX('Matérias-Primas'!$O$5:$O$45,MATCH(A10,'Matérias-Primas'!$A$5:$A$45,0)),0)) -> 0 | O10: =IF(A10="",0,C10*IFERROR(INDEX('Matérias-Primas'!$P$5:$P$45,MATCH(A10,'Matérias-Primas'!$A$5:$A$45,0)),0)) -> 0 | P10: =IF(A10="",0,C10*IFERROR(INDEX('Matérias-Primas'!$Q$5:$Q$45,MATCH(A10,'Matérias-Primas'!$A$5:$A$45,0)),0)) -> 0 | Q10: =IF(A10="",0,C10*IFERROR(INDEX('Matérias-Primas'!$R$5:$R$45,MATCH(A10,'Matérias-Primas'!$A$5:$A$45,0)),0)) -> 0
C11: =IF(B11="","",B11/SUM($B$5:$B$14)) | D11: =IF(A11="","",IFERROR(INDEX('Matérias-Primas'!$D$5:$D$45,MATCH(A11,'Matérias-Primas'!$A$5:$A$45,0)),0)) | E11: =IF(A11="",0,C11*IFERROR(INDEX('Matérias-Primas'!$F$5:$F$45,MATCH(A11,'Matérias-Primas'!$A$5:$A$45,0)),0)) -> 0 | F11: =IF(A11="",0,C11*IFERROR(INDEX('Matérias-Primas'!$G$5:$G$45,MATCH(A11,'Matérias-Primas'!$A$5:$A$45,0)),0)) -> 0 | G11: =IF(A11="",0,C11*IFERROR(INDEX('Matérias-Primas'!$H$5:$H$45,MATCH(A11,'Matérias-Primas'!$A$5:$A$45,0)),0)) -> 0 | H11: =IF(A11="",0,C11*IFERROR(INDEX('Matérias-Primas'!$I$5:$I$45,MATCH(A11,'Matérias-Primas'!$A$5:$A$45,0)),0)) -> 0 | I11: =IF(A11="",0,C11*IFERROR(INDEX('Matérias-Primas'!$J$5:$J$45,MATCH(A11,'Matérias-Primas'!$A$5:$A$45,0)),0)) -> 0 | J11: =IF(A11="",0,C11*IFERROR(INDEX('Matérias-Primas'!$K$5:$K$45,MATCH(A11,'Matérias-Primas'!$A$5:$A$45,0)),0)) -> 0 | K11: =IF(A11="",0,C11*IFERROR(INDEX('Matérias-Primas'!$L$5:$L$45,MATCH(A11,'Matérias-Primas'!$A$5:$A$45,0)),0)) -> 0 | L11: =IF(A11="",0,C11*IFERROR(INDEX('Matérias-Primas'!$M$5:$M$45,MATCH(A11,'Matérias-Primas'!$A$5:$A$45,0)),0)) -> 0 | M11: =IF(A11="",0,C11*IFERROR(INDEX('Matérias-Primas'!$N$5:$N$45,MATCH(A11,'Matérias-Primas'!$A$5:$A$45,0)),0)) -> 0 | N11: =IF(A11="",0,C11*IFERROR(INDEX('Matérias-Primas'!$O$5:$O$45,MATCH(A11,'Matérias-Primas'!$A$5:$A$45,0)),0)) -> 0 | O11: =IF(A11="",0,C11*IFERROR(INDEX('Matérias-Primas'!$P$5:$P$45,MATCH(A11,'Matérias-Primas'!$A$5:$A$45,0)),0)) -> 0 | P11: =IF(A11="",0,C11*IFERROR(INDEX('Matérias-Primas'!$Q$5:$Q$45,MATCH(A11,'Matérias-Primas'!$A$5:$A$45,0)),0)) -> 0 | Q11: =IF(A11="",0,C11*IFERROR(INDEX('Matérias-Primas'!$R$5:$R$45,MATCH(A11,'Matérias-Primas'!$A$5:$A$45,0)),0)) -> 0
C12: =IF(B12="","",B12/SUM($B$5:$B$14)) | D12: =IF(A12="","",IFERROR(INDEX('Matérias-Primas'!$D$5:$D$45,MATCH(A12,'Matérias-Primas'!$A$5:$A$45,0)),0)) | E12: =IF(A12="",0,C12*IFERROR(INDEX('Matérias-Primas'!$F$5:$F$45,MATCH(A12,'Matérias-Primas'!$A$5:$A$45,0)),0)) -> 0 | F12: =IF(A12="",0,C12*IFERROR(INDEX('Matérias-Primas'!$G$5:$G$45,MATCH(A12,'Matérias-Primas'!$A$5:$A$45,0)),0)) -> 0 | G12: =IF(A12="",0,C12*IFERROR(INDEX('Matérias-Primas'!$H$5:$H$45,MATCH(A12,'Matérias-Primas'!$A$5:$A$45,0)),0)) -> 0 | H12: =IF(A12="",0,C12*IFERROR(INDEX('Matérias-Primas'!$I$5:$I$45,MATCH(A12,'Matérias-Primas'!$A$5:$A$45,0)),0)) -> 0 | I12: =IF(A12="",0,C12*IFERROR(INDEX('Matérias-Primas'!$J$5:$J$45,MATCH(A12,'Matérias-Primas'!$A$5:$A$45,0)),0)) -> 0 | J12: =IF(A12="",0,C12*IFERROR(INDEX('Matérias-Primas'!$K$5:$K$45,MATCH(A12,'Matérias-Primas'!$A$5:$A$45,0)),0)) -> 0 | K12: =IF(A12="",0,C12*IFERROR(INDEX('Matérias-Primas'!$L$5:$L$45,MATCH(A12,'Matérias-Primas'!$A$5:$A$45,0)),0)) -> 0 | L12: =IF(A12="",0,C12*IFERROR(INDEX('Matérias-Primas'!$M$5:$M$45,MATCH(A12,'Matérias-Primas'!$A$5:$A$45,0)),0)) -> 0 | M12: =IF(A12="",0,C12*IFERROR(INDEX('Matérias-Primas'!$N$5:$N$45,MATCH(A12,'Matérias-Primas'!$A$5:$A$45,0)),0)) -> 0 | N12: =IF(A12="",0,C12*IFERROR(INDEX('Matérias-Primas'!$O$5:$O$45,MATCH(A12,'Matérias-Primas'!$A$5:$A$45,0)),0)) -> 0 | O12: =IF(A12="",0,C12*IFERROR(INDEX('Matérias-Primas'!$P$5:$P$45,MATCH(A12,'Matérias-Primas'!$A$5:$A$45,0)),0)) -> 0 | P12: =IF(A12="",0,C12*IFERROR(INDEX('Matérias-Primas'!$Q$5:$Q$45,MATCH(A12,'Matérias-Primas'!$A$5:$A$45,0)),0)) -> 0 | Q12: =IF(A12="",0,C12*IFERROR(INDEX('Matérias-Primas'!$R$5:$R$45,MATCH(A12,'Matérias-Primas'!$A$5:$A$45,0)),0)) -> 0
C13: =IF(B13="","",B13/SUM($B$5:$B$14)) | D13: =IF(A13="","",IFERROR(INDEX('Matérias-Primas'!$D$5:$D$45,MATCH(A13,'Matérias-Primas'!$A$5:$A$45,0)),0)) | E13: =IF(A13="",0,C13*IFERROR(INDEX('Matérias-Primas'!$F$5:$F$45,MATCH(A13,'Matérias-Primas'!$A$5:$A$45,0)),0)) -> 0 | F13: =IF(A13="",0,C13*IFERROR(INDEX('Matérias-Primas'!$G$5:$G$45,MATCH(A13,'Matérias-Primas'!$A$5:$A$45,0)),0)) -> 0 | G13: =IF(A13="",0,C13*IFERROR(INDEX('Matérias-Primas'!$H$5:$H$45,MATCH(A13,'Matérias-Primas'!$A$5:$A$45,0)),0)) -> 0 | H13: =IF(A13="",0,C13*IFERROR(INDEX('Matérias-Primas'!$I$5:$I$45,MATCH(A13,'Matérias-Primas'!$A$5:$A$45,0)),0)) -> 0 | I13: =IF(A13="",0,C13*IFERROR(INDEX('Matérias-Primas'!$J$5:$J$45,MATCH(A13,'Matérias-Primas'!$A$5:$A$45,0)),0)) -> 0 | J13: =IF(A13="",0,C13*IFERROR(INDEX('Matérias-Primas'!$K$5:$K$45,MATCH(A13,'Matérias-Primas'!$A$5:$A$45,0)),0)) -> 0 | K13: =IF(A13="",0,C13*IFERROR(INDEX('Matérias-Primas'!$L$5:$L$45,MATCH(A13,'Matérias-Primas'!$A$5:$A$45,0)),0)) -> 0 | L13: =IF(A13="",0,C13*IFERROR(INDEX('Matérias-Primas'!$M$5:$M$45,MATCH(A13,'Matérias-Primas'!$A$5:$A$45,0)),0)) -> 0 | M13: =IF(A13="",0,C13*IFERROR(INDEX('Matérias-Primas'!$N$5:$N$45,MATCH(A13,'Matérias-Primas'!$A$5:$A$45,0)),0)) -> 0 | N13: =IF(A13="",0,C13*IFERROR(INDEX('Matérias-Primas'!$O$5:$O$45,MATCH(A13,'Matérias-Primas'!$A$5:$A$45,0)),0)) -> 0 | O13: =IF(A13="",0,C13*IFERROR(INDEX('Matérias-Primas'!$P$5:$P$45,MATCH(A13,'Matérias-Primas'!$A$5:$A$45,0)),0)) -> 0 | P13: =IF(A13="",0,C13*IFERROR(INDEX('Matérias-Primas'!$Q$5:$Q$45,MATCH(A13,'Matérias-Primas'!$A$5:$A$45,0)),0)) -> 0 | Q13: =IF(A13="",0,C13*IFERROR(INDEX('Matérias-Primas'!$R$5:$R$45,MATCH(A13,'Matérias-Primas'!$A$5:$A$45,0)),0)) -> 0
C14: =IF(B14="","",B14/SUM($B$5:$B$14)) | D14: =IF(A14="","",IFERROR(INDEX('Matérias-Primas'!$D$5:$D$45,MATCH(A14,'Matérias-Primas'!$A$5:$A$45,0)),0)) | E14: =IF(A14="",0,C14*IFERROR(INDEX('Matérias-Primas'!$F$5:$F$45,MATCH(A14,'Matérias-Primas'!$A$5:$A$45,0)),0)) -> 0 | F14: =IF(A14="",0,C14*IFERROR(INDEX('Matérias-Primas'!$G$5:$G$45,MATCH(A14,'Matérias-Primas'!$A$5:$A$45,0)),0)) -> 0 | G14: =IF(A14="",0,C14*IFERROR(INDEX('Matérias-Primas'!$H$5:$H$45,MATCH(A14,'Matérias-Primas'!$A$5:$A$45,0)),0)) -> 0 | H14: =IF(A14="",0,C14*IFERROR(INDEX('Matérias-Primas'!$I$5:$I$45,MATCH(A14,'Matérias-Primas'!$A$5:$A$45,0)),0)) -> 0 | I14: =IF(A14="",0,C14*IFERROR(INDEX('Matérias-Primas'!$J$5:$J$45,MATCH(A14,'Matérias-Primas'!$A$5:$A$45,0)),0)) -> 0 | J14: =IF(A14="",0,C14*IFERROR(INDEX('Matérias-Primas'!$K$5:$K$45,MATCH(A14,'Matérias-Primas'!$A$5:$A$45,0)),0)) -> 0 | K14: =IF(A14="",0,C14*IFERROR(INDEX('Matérias-Primas'!$L$5:$L$45,MATCH(A14,'Matérias-Primas'!$A$5:$A$45,0)),0)) -> 0 | L14: =IF(A14="",0,C14*IFERROR(INDEX('Matérias-Primas'!$M$5:$M$45,MATCH(A14,'Matérias-Primas'!$A$5:$A$45,0)),0)) -> 0 | M14: =IF(A14="",0,C14*IFERROR(INDEX('Matérias-Primas'!$N$5:$N$45,MATCH(A14,'Matérias-Primas'!$A$5:$A$45,0)),0)) -> 0 | N14: =IF(A14="",0,C14*IFERROR(INDEX('Matérias-Primas'!$O$5:$O$45,MATCH(A14,'Matérias-Primas'!$A$5:$A$45,0)),0)) -> 0 | O14: =IF(A14="",0,C14*IFERROR(INDEX('Matérias-Primas'!$P$5:$P$45,MATCH(A14,'Matérias-Primas'!$A$5:$A$45,0)),0)) -> 0 | P14: =IF(A14="",0,C14*IFERROR(INDEX('Matérias-Primas'!$Q$5:$Q$45,MATCH(A14,'Matérias-Primas'!$A$5:$A$45,0)),0)) -> 0 | Q14: =IF(A14="",0,C14*IFERROR(INDEX('Matérias-Primas'!$R$5:$R$45,MATCH(A14,'Matérias-Primas'!$A$5:$A$45,0)),0)) -> 0
A15: Total | B15: =SUM(B5:B14) -> 100 | C15: =SUM(C5:C14) -> 1 | E15: =SUM(E5:E14) -> 53.679 | F15: =SUM(F5:F14) -> 15.425 | G15: =SUM(G5:G14) -> 2.772 | H15: =SUM(H5:H14) -> 2.136 | I15: =SUM(I5:I14) -> 3.3 | J15: =SUM(J5:J14) -> 0 | K15: =SUM(K5:K14) -> 16.458 | L15: =SUM(L5:L14) -> 0 | ... Q15: =SUM(Q5:Q14) -> 0
A16: Massa molar | E16: ='Matérias-Primas'!F3 -> 60.08 | F16: ='Matérias-Primas'!G3 -> 101.96 | G16: ='Matérias-Primas'!H3 -> 69.62 | H16: ='Matérias-Primas'!I3 -> 61.98 | I16: ='Matérias-Primas'!J3 -> 94.2 | J16: ='Matérias-Primas'!K3 -> 29.88 | K16: ='Matérias-Primas'!L3 -> 56.08 | L16: ='Matérias-Primas'!M3 -> 40.3 | ... Q16: ='Matérias-Primas'!R3 -> 79.87
A17: Mols | C17: Soma fundentes: | D17: =H17+I17+J17+K17+L17+M17+N17 -> 0.36296819 | E17: =E15/E16 -> 0.89345872 | F17: =F15/F16 -> 0.15128482 | G17: =G15/G16 -> 0.039816145 | H17: =H15/H16 -> 0.03446273 | I17: =I15/I16 -> 0.035031847 | J17: =J15/J16 -> 0 | K17: =K15/K16 -> 0.29347361 | L17: =L15/L16 -> 0 | ... Q17: =Q15/Q16 -> 0
A18: UMF (fundentes = 1) | E18: =IF($D$17=0,0,E17/$D$17) -> 2.4615345 | F18: =IF($D$17=0,0,F17/$D$17) -> 0.41679911 | G18: =IF($D$17=0,0,G17/$D$17) -> 0.10969596 | H18: =IF($D$17=0,0,H17/$D$17) -> 0.094946971 | I18: =IF($D$17=0,0,I17/$D$17) -> 0.096514925 | J18: =IF($D$17=0,0,J17/$D$17) -> 0 | K18: =IF($D$17=0,0,K17/$D$17) -> 0.8085381 | L18: =IF($D$17=0,0,L17/$D$17) -> 0 | ... Q18: =IF($D$17=0,0,Q17/$D$17) -> 0
A20: Checagem contra faixas-alvo
A21: Indicador | B21: Valor | C21: Mín | D21: Máx | E21: Status
A22: SiO₂ (UMF) | B22: =E18 -> 2.4615345 | C22: 2 | D22: 3 | E22: =IF(AND(B22>=C22,B22<=D22),"OK","Ajustar") -> OK
A23: Al₂O₃ (UMF) | B23: =F18 -> 0.41679911 | C23: 0.35 | D23: 0.5 | E23: =IF(AND(B23>=C23,B23<=D23),"OK","Ajustar") -> OK
A24: B₂O₃ (UMF) | B24: =G18 -> 0.10969596 | C24: 0.1 | D24: 0.25 | E24: =IF(AND(B24>=C24,B24<=D24),"OK","Ajustar") -> OK
A25: Razão SiO₂:Al₂O₃ | B25: =IF(F18=0,0,E18/F18) -> 5.9058056 | C25: 5 | D25: 7 | E25: =IF(AND(B25>=C25,B25<=D25),"OK","Ajustar") -> OK
A27: Custo matéria-prima da base (R$/kg) | B27: =SUMPRODUCT(C5:C14,D5:D14) -> 5.455
A28: Faixas-alvo são referências de literatura para cone 6 estável; ajuste-as conforme seus testes. Fórmula-alvo calculada sobre óxidos; colorantes entram na aba Cores.

Sheet Base C
A1: Base C — Brilhante de estrôncio (para branco opaco e turquesa)
A2: Estrôncio no lugar de bário: favorece turquesa com cobre.
E3: Contribuição em massa de cada óxido (g por 100 g de esmalte queimado não normalizado) →
A4: Material | B4: Quantidade (g) | C4: % normalizado | D4: Preço (R$/kg) | E4: SiO2 | F4: Al2O3 | G4: B2O3 | H4: Na2O | I4: K2O | J4: Li2O | K4: CaO | L4: MgO | M4: SrO | N4: ZnO | O4: ZrO2 | P4: Fe2O3 | Q4: TiO2
A5: Feldspato potássico | B5: 25 | C5: =IF(B5="","",B5/SUM($B$5:$B$14)) -> 0.25 | D5: =IF(A5="","",IFERROR(INDEX('Matérias-Primas'!$D$5:$D$45,MATCH(A5,'Matérias-Primas'!$A$5:$A$45,0)),0)) -> 3.5 | E5: =IF(A5="",0,C5*IFERROR(INDEX('Matérias-Primas'!$F$5:$F$45,MATCH(A5,'Matérias-Primas'!$A$5:$A$45,0)),0)) -> 16.75 | F5: =IF(A5="",0,C5*IFERROR(INDEX('Matérias-Primas'!$G$5:$G$45,MATCH(A5,'Matérias-Primas'!$A$5:$A$45,0)),0)) -> 4.625 | G5: =IF(A5="",0,C5*IFERROR(INDEX('Matérias-Primas'!$H$5:$H$45,MATCH(A5,'Matérias-Primas'!$A$5:$A$45,0)),0)) -> 0 | H5: =IF(A5="",0,C5*IFERROR(INDEX('Matérias-Primas'!$I$5:$I$45,MATCH(A5,'Matérias-Primas'!$A$5:$A$45,0)),0)) -> 0.75 | I5: =IF(A5="",0,C5*IFERROR(INDEX('Matérias-Primas'!$J$5:$J$45,MATCH(A5,'Matérias-Primas'!$A$5:$A$45,0)),0)) -> 2.75 | J5: =IF(A5="",0,C5*IFERROR(INDEX('Matérias-Primas'!$K$5:$K$45,MATCH(A5,'Matérias-Primas'!$A$5:$A$45,0)),0)) -> 0 | K5: =IF(A5="",0,C5*IFERROR(INDEX('Matérias-Primas'!$L$5:$L$45,MATCH(A5,'Matérias-Primas'!$A$5:$A$45,0)),0)) -> 0.05 | L5: =IF(A5="",0,C5*IFERROR(INDEX('Matérias-Primas'!$M$5:$M$45,MATCH(A5,'Matérias-Primas'!$A$5:$A$45,0)),0)) -> 0 | M5: =IF(A5="",0,C5*IFERROR(INDEX('Matérias-Primas'!$N$5:$N$45,MATCH(A5,'Matérias-Primas'!$A$5:$A$45,0)),0)) -> 0 | N5: =IF(A5="",0,C5*IFERROR(INDEX('Matérias-Primas'!$O$5:$O$45,MATCH(A5,'Matérias-Primas'!$A$5:$A$45,0)),0)) -> 0 | O5: =IF(A5="",0,C5*IFERROR(INDEX('Matérias-Primas'!$P$5:$P$45,MATCH(A5,'Matérias-Primas'!$A$5:$A$45,0)),0)) -> 0 | P5: =IF(A5="",0,C5*IFERROR(INDEX('Matérias-Primas'!$Q$5:$Q$45,MATCH(A5,'Matérias-Primas'!$A$5:$A$45,0)),0)) -> 0.025 | Q5: =IF(A5="",0,C5*IFERROR(INDEX('Matérias-Primas'!$R$5:$R$45,MATCH(A5,'Matérias-Primas'!$A$5:$A$45,0)),0)) -> 0
A6: Frita borácica | B6: 18 | C6: =IF(B6="","",B6/SUM($B$5:$B$14)) -> 0.18 | D6: =IF(A6="","",IFERROR(INDEX('Matérias-Primas'!$D$5:$D$45,MATCH(A6,'Matérias-Primas'!$A$5:$A$45,0)),0)) -> 15 | E6: =IF(A6="",0,C6*IFERROR(INDEX('Matérias-Primas'!$F$5:$F$45,MATCH(A6,'Matérias-Primas'!$A$5:$A$45,0)),0)) -> 8.37 | F6: =IF(A6="",0,C6*IFERROR(INDEX('Matérias-Primas'!$G$5:$G$45,MATCH(A6,'Matérias-Primas'!$A$5:$A$45,0)),0)) -> 0 | G6: =IF(A6="",0,C6*IFERROR(INDEX('Matérias-Primas'!$H$5:$H$45,MATCH(A6,'Matérias-Primas'!$A$5:$A$45,0)),0)) -> 4.158 | H6: =IF(A6="",0,C6*IFERROR(INDEX('Matérias-Primas'!$I$5:$I$45,MATCH(A6,'Matérias-Primas'!$A$5:$A$45,0)),0)) -> 1.854 | I6: =IF(A6="",0,C6*IFERROR(INDEX('Matérias-Primas'!$J$5:$J$45,MATCH(A6,'Matérias-Primas'!$A$5:$A$45,0)),0)) -> 0 | J6: =IF(A6="",0,C6*IFERROR(INDEX('Matérias-Primas'!$K$5:$K$45,MATCH(A6,'Matérias-Primas'!$A$5:$A$45,0)),0)) -> 0 | K6: =IF(A6="",0,C6*IFERROR(INDEX('Matérias-Primas'!$L$5:$L$45,MATCH(A6,'Matérias-Primas'!$A$5:$A$45,0)),0)) -> 3.618 | L6: =IF(A6="",0,C6*IFERROR(INDEX('Matérias-Primas'!$M$5:$M$45,MATCH(A6,'Matérias-Primas'!$A$5:$A$45,0)),0)) -> 0 | M6: =IF(A6="",0,C6*IFERROR(INDEX('Matérias-Primas'!$N$5:$N$45,MATCH(A6,'Matérias-Primas'!$A$5:$A$45,0)),0)) -> 0 | N6: =IF(A6="",0,C6*IFERROR(INDEX('Matérias-Primas'!$O$5:$O$45,MATCH(A6,'Matérias-Primas'!$A$5:$A$45,0)),0)) -> 0 | O6: =IF(A6="",0,C6*IFERROR(INDEX('Matérias-Primas'!$P$5:$P$45,MATCH(A6,'Matérias-Primas'!$A$5:$A$45,0)),0)) -> 0 | P6: =IF(A6="",0,C6*IFERROR(INDEX('Matérias-Primas'!$Q$5:$Q$45,MATCH(A6,'Matérias-Primas'!$A$5:$A$45,0)),0)) -> 0 | Q6: =IF(A6="",0,C6*IFERROR(INDEX('Matérias-Primas'!$R$5:$R$45,MATCH(A6,'Matérias-Primas'!$A$5:$A$45,0)),0)) -> 0
A7: Carbonato de estrôncio | B7: 10 | C7: =IF(B7="","",B7/SUM($B$5:$B$14)) -> 0.1 | D7: =IF(A7="","",IFERROR(INDEX('Matérias-Primas'!$D$5:$D$45,MATCH(A7,'Matérias-Primas'!$A$5:$A$45,0)),0)) -> 35 | E7: =IF(A7="",0,C7*IFERROR(INDEX('Matérias-Primas'!$F$5:$F$45,MATCH(A7,'Matérias-Primas'!$A$5:$A$45,0)),0)) -> 0 | F7: =IF(A7="",0,C7*IFERROR(INDEX('Matérias-Primas'!$G$5:$G$45,MATCH(A7,'Matérias-Primas'!$A$5:$A$45,0)),0)) -> 0 | G7: =IF(A7="",0,C7*IFERROR(INDEX('Matérias-Primas'!$H$5:$H$45,MATCH(A7,'Matérias-Primas'!$A$5:$A$45,0)),0)) -> 0 | H7: =IF(A7="",0,C7*IFERROR(INDEX('Matérias-Primas'!$I$5:$I$45,MATCH(A7,'Matérias-Primas'!$A$5:$A$45,0)),0)) -> 0 | I7: =IF(A7="",0,C7*IFERROR(INDEX('Matérias-Primas'!$J$5:$J$45,MATCH(A7,'Matérias-Primas'!$A$5:$A$45,0)),0)) -> 0 | J7: =IF(A7="",0,C7*IFERROR(INDEX('Matérias-Primas'!$K$5:$K$45,MATCH(A7,'Matérias-Primas'!$A$5:$A$45,0)),0)) -> 0 | K7: =IF(A7="",0,C7*IFERROR(INDEX('Matérias-Primas'!$L$5:$L$45,MATCH(A7,'Matérias-Primas'!$A$5:$A$45,0)),0)) -> 0 | L7: =IF(A7="",0,C7*IFERROR(INDEX('Matérias-Primas'!$M$5:$M$45,MATCH(A7,'Matérias-Primas'!$A$5:$A$45,0)),0)) -> 0 | M7: =IF(A7="",0,C7*IFERROR(INDEX('Matérias-Primas'!$N$5:$N$45,MATCH(A7,'Matérias-Primas'!$A$5:$A$45,0)),0)) -> 7.02 | N7: =IF(A7="",0,C7*IFERROR(INDEX('Matérias-Primas'!$O$5:$O$45,MATCH(A7,'Matérias-Primas'!$A$5:$A$45,0)),0)) -> 0 | O7: =IF(A7="",0,C7*IFERROR(INDEX('Matérias-Primas'!$P$5:$P$45,MATCH(A7,'Matérias-Primas'!$A$5:$A$45,0)),0)) -> 0 | P7: =IF(A7="",0,C7*IFERROR(INDEX('Matérias-Primas'!$Q$5:$Q$45,MATCH(A7,'Matérias-Primas'!$A$5:$A$45,0)),0)) -> 0 | Q7: =IF(A7="",0,C7*IFERROR(INDEX('Matérias-Primas'!$R$5:$R$45,MATCH(A7,'Matérias-Primas'!$A$5:$A$45,0)),0)) -> 0
A8: Wollastonita | B8: 10 | C8: =IF(B8="","",B8/SUM($B$5:$B$14)) -> 0.1 | D8: =IF(A8="","",IFERROR(INDEX('Matérias-Primas'!$D$5:$D$45,MATCH(A8,'Matérias-Primas'!$A$5:$A$45,0)),0)) -> 8 | E8: =IF(A8="",0,C8*IFERROR(INDEX('Matérias-Primas'!$F$5:$F$45,MATCH(A8,'Matérias-Primas'!$A$5:$A$45,0)),0)) -> 5.17 | F8: =IF(A8="",0,C8*IFERROR(INDEX('Matérias-Primas'!$G$5:$G$45,MATCH(A8,'Matérias-Primas'!$A$5:$A$45,0)),0)) -> 0 | G8: =IF(A8="",0,C8*IFERROR(INDEX('Matérias-Primas'!$H$5:$H$45,MATCH(A8,'Matérias-Primas'!$A$5:$A$45,0)),0)) -> 0 | H8: =IF(A8="",0,C8*IFERROR(INDEX('Matérias-Primas'!$I$5:$I$45,MATCH(A8,'Matérias-Primas'!$A$5:$A$45,0)),0)) -> 0 | I8: =IF(A8="",0,C8*IFERROR(INDEX('Matérias-Primas'!$J$5:$J$45,MATCH(A8,'Matérias-Primas'!$A$5:$A$45,0)),0)) -> 0 | J8: =IF(A8="",0,C8*IFERROR(INDEX('Matérias-Primas'!$K$5:$K$45,MATCH(A8,'Matérias-Primas'!$A$5:$A$45,0)),0)) -> 0 | K8: =IF(A8="",0,C8*IFERROR(INDEX('Matérias-Primas'!$L$5:$L$45,MATCH(A8,'Matérias-Primas'!$A$5:$A$45,0)),0)) -> 4.83 | L8: =IF(A8="",0,C8*IFERROR(INDEX('Matérias-Primas'!$M$5:$M$45,MATCH(A8,'Matérias-Primas'!$A$5:$A$45,0)),0)) -> 0 | M8: =IF(A8="",0,C8*IFERROR(INDEX('Matérias-Primas'!$N$5:$N$45,MATCH(A8,'Matérias-Primas'!$A$5:$A$45,0)),0)) -> 0 | N8: =IF(A8="",0,C8*IFERROR(INDEX('Matérias-Primas'!$O$5:$O$45,MATCH(A8,'Matérias-Primas'!$A$5:$A$45,0)),0)) -> 0 | O8: =IF(A8="",0,C8*IFERROR(INDEX('Matérias-Primas'!$P$5:$P$45,MATCH(A8,'Matérias-Primas'!$A$5:$A$45,0)),0)) -> 0 | P8: =IF(A8="",0,C8*IFERROR(INDEX('Matérias-Primas'!$Q$5:$Q$45,MATCH(A8,'Matérias-Primas'!$A$5:$A$45,0)),0)) -> 0 | Q8: =IF(A8="",0,C8*IFERROR(INDEX('Matérias-Primas'!$R$5:$R$45,MATCH(A8,'Matérias-Primas'!$A$5:$A$45,0)),0)) -> 0
A9: Caulim | B9: 15 | C9: =IF(B9="","",B9/SUM($B$5:$B$14)) -> 0.15 | D9: =IF(A9="","",IFERROR(INDEX('Matérias-Primas'!$D$5:$D$45,MATCH(A9,'Matérias-Primas'!$A$5:$A$45,0)),0)) -> 2.5 | E9: =IF(A9="",0,C9*IFERROR(INDEX('Matérias-Primas'!$F$5:$F$45,MATCH(A9,'Matérias-Primas'!$A$5:$A$45,0)),0)) -> 6.975 | F9: =IF(A9="",0,C9*IFERROR(INDEX('Matérias-Primas'!$G$5:$G$45,MATCH(A9,'Matérias-Primas'!$A$5:$A$45,0)),0)) -> 5.925 | G9: =IF(A9="",0,C9*IFERROR(INDEX('Matérias-Primas'!$H$5:$H$45,MATCH(A9,'Matérias-Primas'!$A$5:$A$45,0)),0)) -> 0 | H9: =IF(A9="",0,C9*IFERROR(INDEX('Matérias-Primas'!$I$5:$I$45,MATCH(A9,'Matérias-Primas'!$A$5:$A$45,0)),0)) -> 0 | I9: =IF(A9="",0,C9*IFERROR(INDEX('Matérias-Primas'!$J$5:$J$45,MATCH(A9,'Matérias-Primas'!$A$5:$A$45,0)),0)) -> 0 | J9: =IF(A9="",0,C9*IFERROR(INDEX('Matérias-Primas'!$K$5:$K$45,MATCH(A9,'Matérias-Primas'!$A$5:$A$45,0)),0)) -> 0 | K9: =IF(A9="",0,C9*IFERROR(INDEX('Matérias-Primas'!$L$5:$L$45,MATCH(A9,'Matérias-Primas'!$A$5:$A$45,0)),0)) -> 0 | L9: =IF(A9="",0,C9*IFERROR(INDEX('Matérias-Primas'!$M$5:$M$45,MATCH(A9,'Matérias-Primas'!$A$5:$A$45,0)),0)) -> 0 | M9: =IF(A9="",0,C9*IFERROR(INDEX('Matérias-Primas'!$N$5:$N$45,MATCH(A9,'Matérias-Primas'!$A$5:$A$45,0)),0)) -> 0 | N9: =IF(A9="",0,C9*IFERROR(INDEX('Matérias-Primas'!$O$5:$O$45,MATCH(A9,'Matérias-Primas'!$A$5:$A$45,0)),0)) -> 0 | O9: =IF(A9="",0,C9*IFERROR(INDEX('Matérias-Primas'!$P$5:$P$45,MATCH(A9,'Matérias-Primas'!$A$5:$A$45,0)),0)) -> 0 | P9: =IF(A9="",0,C9*IFERROR(INDEX('Matérias-Primas'!$Q$5:$Q$45,MATCH(A9,'Matérias-Primas'!$A$5:$A$45,0)),0)) -> 0.015 | Q9: =IF(A9="",0,C9*IFERROR(INDEX('Matérias-Primas'!$R$5:$R$45,MATCH(A9,'Matérias-Primas'!$A$5:$A$45,0)),0)) -> 0
A10: Quartzo (sílica 325#) | B10: 22 | C10: =IF(B10="","",B10/SUM($B$5:$B$14)) -> 0.22 | D10: =IF(A10="","",IFERROR(INDEX('Matérias-Primas'!$D$5:$D$45,MATCH(A10,'Matérias-Primas'!$A$5:$A$45,0)),0)) -> 2 | E10: =IF(A10="",0,C10*IFERROR(INDEX('Matérias-Primas'!$F$5:$F$45,MATCH(A10,'Matérias-Primas'!$A$5:$A$45,0)),0)) -> 22 | F10: =IF(A10="",0,C10*IFERROR(INDEX('Matérias-Primas'!$G$5:$G$45,MATCH(A10,'Matérias-Primas'!$A$5:$A$45,0)),0)) -> 0 | G10: =IF(A10="",0,C10*IFERROR(INDEX('Matérias-Primas'!$H$5:$H$45,MATCH(A10,'Matérias-Primas'!$A$5:$A$45,0)),0)) -> 0 | H10: =IF(A10="",0,C10*IFERROR(INDEX('Matérias-Primas'!$I$5:$I$45,MATCH(A10,'Matérias-Primas'!$A$5:$A$45,0)),0)) -> 0 | I10: =IF(A10="",0,C10*IFERROR(INDEX('Matérias-Primas'!$J$5:$J$45,MATCH(A10,'Matérias-Primas'!$A$5:$A$45,0)),0)) -> 0 | J10: =IF(A10="",0,C10*IFERROR(INDEX('Matérias-Primas'!$K$5:$K$45,MATCH(A10,'Matérias-Primas'!$A$5:$A$45,0)),0)) -> 0 | K10: =IF(A10="",0,C10*IFERROR(INDEX('Matérias-Primas'!$L$5:$L$45,MATCH(A10,'Matérias-Primas'!$A$5:$A$45,0)),0)) -> 0 | L10: =IF(A10="",0,C10*IFERROR(INDEX('Matérias-Primas'!$M$5:$M$45,MATCH(A10,'Matérias-Primas'!$A$5:$A$45,0)),0)) -> 0 | M10: =IF(A10="",0,C10*IFERROR(INDEX('Matérias-Primas'!$N$5:$N$45,MATCH(A10,'Matérias-Primas'!$A$5:$A$45,0)),0)) -> 0 | N10: =IF(A10="",0,C10*IFERROR(INDEX('Matérias-Primas'!$O$5:$O$45,MATCH(A10,'Matérias-Primas'!$A$5:$A$45,0)),0)) -> 0 | O10: =IF(A10="",0,C10*IFERROR(INDEX('Matérias-Primas'!$P$5:$P$45,MATCH(A10,'Matérias-Primas'!$A$5:$A$45,0)),0)) -> 0 | P10: =IF(A10="",0,C10*IFERROR(INDEX('Matérias-Primas'!$Q$5:$Q$45,MATCH(A10,'Matérias-Primas'!$A$5:$A$45,0)),0)) -> 0 | Q10: =IF(A10="",0,C10*IFERROR(INDEX('Matérias-Primas'!$R$5:$R$45,MATCH(A10,'Matérias-Primas'!$A$5:$A$45,0)),0)) -> 0
C11: =IF(B11="","",B11/SUM($B$5:$B$14)) | D11: =IF(A11="","",IFERROR(INDEX('Matérias-Primas'!$D$5:$D$45,MATCH(A11,'Matérias-Primas'!$A$5:$A$45,0)),0)) | E11: =IF(A11="",0,C11*IFERROR(INDEX('Matérias-Primas'!$F$5:$F$45,MATCH(A11,'Matérias-Primas'!$A$5:$A$45,0)),0)) -> 0 | F11: =IF(A11="",0,C11*IFERROR(INDEX('Matérias-Primas'!$G$5:$G$45,MATCH(A11,'Matérias-Primas'!$A$5:$A$45,0)),0)) -> 0 | G11: =IF(A11="",0,C11*IFERROR(INDEX('Matérias-Primas'!$H$5:$H$45,MATCH(A11,'Matérias-Primas'!$A$5:$A$45,0)),0)) -> 0 | H11: =IF(A11="",0,C11*IFERROR(INDEX('Matérias-Primas'!$I$5:$I$45,MATCH(A11,'Matérias-Primas'!$A$5:$A$45,0)),0)) -> 0 | I11: =IF(A11="",0,C11*IFERROR(INDEX('Matérias-Primas'!$J$5:$J$45,MATCH(A11,'Matérias-Primas'!$A$5:$A$45,0)),0)) -> 0 | J11: =IF(A11="",0,C11*IFERROR(INDEX('Matérias-Primas'!$K$5:$K$45,MATCH(A11,'Matérias-Primas'!$A$5:$A$45,0)),0)) -> 0 | K11: =IF(A11="",0,C11*IFERROR(INDEX('Matérias-Primas'!$L$5:$L$45,MATCH(A11,'Matérias-Primas'!$A$5:$A$45,0)),0)) -> 0 | L11: =IF(A11="",0,C11*IFERROR(INDEX('Matérias-Primas'!$M$5:$M$45,MATCH(A11,'Matérias-Primas'!$A$5:$A$45,0)),0)) -> 0 | M11: =IF(A11="",0,C11*IFERROR(INDEX('Matérias-Primas'!$N$5:$N$45,MATCH(A11,'Matérias-Primas'!$A$5:$A$45,0)),0)) -> 0 | N11: =IF(A11="",0,C11*IFERROR(INDEX('Matérias-Primas'!$O$5:$O$45,MATCH(A11,'Matérias-Primas'!$A$5:$A$45,0)),0)) -> 0 | O11: =IF(A11="",0,C11*IFERROR(INDEX('Matérias-Primas'!$P$5:$P$45,MATCH(A11,'Matérias-Primas'!$A$5:$A$45,0)),0)) -> 0 | P11: =IF(A11="",0,C11*IFERROR(INDEX('Matérias-Primas'!$Q$5:$Q$45,MATCH(A11,'Matérias-Primas'!$A$5:$A$45,0)),0)) -> 0 | Q11: =IF(A11="",0,C11*IFERROR(INDEX('Matérias-Primas'!$R$5:$R$45,MATCH(A11,'Matérias-Primas'!$A$5:$A$45,0)),0)) -> 0
C12: =IF(B12="","",B12/SUM($B$5:$B$14)) | D12: =IF(A12="","",IFERROR(INDEX('Matérias-Primas'!$D$5:$D$45,MATCH(A12,'Matérias-Primas'!$A$5:$A$45,0)),0)) | E12: =IF(A12="",0,C12*IFERROR(INDEX('Matérias-Primas'!$F$5:$F$45,MATCH(A12,'Matérias-Primas'!$A$5:$A$45,0)),0)) -> 0 | F12: =IF(A12="",0,C12*IFERROR(INDEX('Matérias-Primas'!$G$5:$G$45,MATCH(A12,'Matérias-Primas'!$A$5:$A$45,0)),0)) -> 0 | G12: =IF(A12="",0,C12*IFERROR(INDEX('Matérias-Primas'!$H$5:$H$45,MATCH(A12,'Matérias-Primas'!$A$5:$A$45,0)),0)) -> 0 | H12: =IF(A12="",0,C12*IFERROR(INDEX('Matérias-Primas'!$I$5:$I$45,MATCH(A12,'Matérias-Primas'!$A$5:$A$45,0)),0)) -> 0 | I12: =IF(A12="",0,C12*IFERROR(INDEX('Matérias-Primas'!$J$5:$J$45,MATCH(A12,'Matérias-Primas'!$A$5:$A$45,0)),0)) -> 0 | J12: =IF(A12="",0,C12*IFERROR(INDEX('Matérias-Primas'!$K$5:$K$45,MATCH(A12,'Matérias-Primas'!$A$5:$A$45,0)),0)) -> 0 | K12: =IF(A12="",0,C12*IFERROR(INDEX('Matérias-Primas'!$L$5:$L$45,MATCH(A12,'Matérias-Primas'!$A$5:$A$45,0)),0)) -> 0 | L12: =IF(A12="",0,C12*IFERROR(INDEX('Matérias-Primas'!$M$5:$M$45,MATCH(A12,'Matérias-Primas'!$A$5:$A$45,0)),0)) -> 0 | M12: =IF(A12="",0,C12*IFERROR(INDEX('Matérias-Primas'!$N$5:$N$45,MATCH(A12,'Matérias-Primas'!$A$5:$A$45,0)),0)) -> 0 | N12: =IF(A12="",0,C12*IFERROR(INDEX('Matérias-Primas'!$O$5:$O$45,MATCH(A12,'Matérias-Primas'!$A$5:$A$45,0)),0)) -> 0 | O12: =IF(A12="",0,C12*IFERROR(INDEX('Matérias-Primas'!$P$5:$P$45,MATCH(A12,'Matérias-Primas'!$A$5:$A$45,0)),0)) -> 0 | P12: =IF(A12="",0,C12*IFERROR(INDEX('Matérias-Primas'!$Q$5:$Q$45,MATCH(A12,'Matérias-Primas'!$A$5:$A$45,0)),0)) -> 0 | Q12: =IF(A12="",0,C12*IFERROR(INDEX('Matérias-Primas'!$R$5:$R$45,MATCH(A12,'Matérias-Primas'!$A$5:$A$45,0)),0)) -> 0
